Workbook
Name DataProveedores: [1]Data!$B$1:$C$59

Sheet 17
K1: 668.077 | AG1: Profit Terminos | AH1: Au Real (con Rec) | AI1: Profit RC | AJ1: Au Comprado | AL1: Valor
I2: =SUBTOTAL(9,I4:I9311) -> 702.8 | K2: =SUBTOTAL(9,K4:K9311) -> 667.44742 | L2: =SUMPRODUCT(L5:L142,K5:K142)/K2 -> 0.36470039 | Q2: =+SUMPRODUCT(Q5:Q94,AH5:AH94)/SUM(AH5:AH94) -> 89.914313 | R2: =+SUMPRODUCT(R5:R94,AH5:AH94)/SUM(AH5:AH94) -> 2662.2923 | AG2: =SUMPRODUCT($AG5:$AG94,$K5:$K94)/SUM($K5:$K94) -> 68.04762 | AI2: 2820
A3: Lote | B3: F emision | C3: F recepcion | D3: Nombre | E3: RUC | F3: Minero | G3: Sacos | I3: TMH | J3: %H2O | K3: TMS | L3: Oz/tc Planta | M3: Oz/tc comercial | N3: Oz/tc Minero | O3: Oz/tc Pomedio | P3: % Rec Liq | Q3: % Rec Planta | R3: Inter US$ | S3: TC US$ x tc | T3: Bono | U3: Riesgo | V3: Factor | W3: Soda | X3: Cianuro | Y3: Gasto acopio x tm | Z3: Insumos planta x tm | AA3: Insumos liq x tm | AB3: Precio x TMS | AC3: profit maquila | AD3: Profit Rec | AE3: Profit Consumo | AF3: Profit Leyes | AG3: Profit Total $/TM | AH3: =SUBTOTAL(9,AH5:AH9312) -> 7503.7465 | AI3: =SUMPRODUCT(K5:K94,AI5:AI94)/K2 -> 92.393031 | AJ3: =SUBTOTAL(9,AJ5:AJ9312) -> 7351.0089 | AL3: =SUBTOTAL(9,AL5:AL9312) -> 499002.41
A5: IP-782 | C5: 45624 | D5: ZICAMP S.A.C. | E5: {=XLOOKUP(D5,RUC!$B$3:$B$79,RUC!$D$3:$D$79)} -> #N/A | F5: Hernan Mamani | H5: LLAMPO | I5: 9.36 | J5: 17.35 | K5: =+I5-(I5*(J5/100)) -> 7.73604 | L5: 0.079 | M5: 0.069 | N5: 0.069 | O5: =+ROUND((M5+N5)/2,3) -> 0.069 | P5: 90 | Q5: 85.3 | R5: 2641.85 | S5: =IF((90+ROUNDDOWN(O5,1)*100)<95,95,(90+ROUNDDOWN(O5,1)*100)) -> 95 | U5: 100 | V5: 1.1023 | Y5: 20 | Z5: =IF(IF(D5="UNTUCA",IF(+((W5-3)*1.5+(X5-3)*3.1)>0,+((W5-3)*1.5+(X5-3)*3.1),0),IF(+((W5-3)*1.5+(X5-3)*3.1)>0,+((W5-3)*1.5+(X5-3)*3.1),0))<30,30,IF(D5="UNTUCA",IF(+((W5-3)*1.5+(X5-3)*3.1)>0,+((W5-3)*1.5+(X5-3)*3.1),0),IF(+((W5-3)*1.5+(X5-3)*3.1)>0,+((W5-3)*1.5+(X5-3)*3.1),0))) -> 30 | AA5: =+Y5+Z5 -> 50 | AB5: 0 | AC5: =+(S5-T5)*V5-'data 1'!$F$4 -> 24.7185 | AD5: =+(Q5-P5)*(R5-U5)*L5*V5/100 -> -10.403385 | AE5: =+(Y5*V5-70)+V5*(Z5-IF(D5="UNTUCA",IF(+((W5-3)*2.5+(X5-3)*3.1)>0,+((W5-3)*1.5+(X5-3)*3.1),0),IF(+((W5-3)*1.5+(X5-3)*3.1)>0,+((W5-3)*1.5+(X5-3)*3.1),0))) -> -14.885 | AF5: =(L5-O5)*(R5-U5)*Q5*V5/100 -> 23.900047 | AG5: =+IF(D5="RONALD WILLIAN GARIBAY ESCUDERO",AC5+AD5+AE5+AF5+70,AC5+AD5+AE5+AF5) -> 23.330162 | AH5: =31.1035*L5*Q5*1.1023*K5/100 -> 17.873265 | AI5: =+((+$AI$2-R5+U5)*L5*Q5*V5)/100 -> 20.661174 | AJ5: =31.1035*1.1023*K5*P5*O5/100 -> 16.470978 | AL5: 0
A6: IP-783 | C6: 45624 | D6: ZICAMP S.A.C. | E6: {=XLOOKUP(D6,RUC!$B$3:$B$79,RUC!$D$3:$D$79)} -> #N/A | F6: Hernan Mamani | H6: LLAMPO | I6: 4.62 | J6: 18.15 | K6: =+I6-(I6*(J6/100)) -> 3.78147 | L6: 0.072 | M6: 0.062 | N6: 0.062 | O6: =+ROUND((M6+N6)/2,3) -> 0.062 | P6: 90 | Q6: 85.42 | R6: 2641.85 | S6: =IF((90+ROUNDDOWN(O6,1)*100)<95,95,(90+ROUNDDOWN(O6,1)*100)) -> 95 | U6: 100 | V6: 1.1023 | Y6: 20 | Z6: =IF(IF(D6="UNTUCA",IF(+((W6-3)*1.5+(X6-3)*3.1)>0,+((W6-3)*1.5+(X6-3)*3.1),0),IF(+((W6-3)*1.5+(X6-3)*3.1)>0,+((W6-3)*1.5+(X6-3)*3.1),0))<30,30,IF(D6="UNTUCA",IF(+((W6-3)*1.5+(X6-3)*3.1)>0,+((W6-3)*1.5+(X6-3)*3.1),0),IF(+((W6-3)*1.5+(X6-3)*3.1)>0,+((W6-3)*1.5+(X6-3)*3.1),0))) -> 30 | AA6: =+Y6+Z6 -> 50 | AB6: 0 | AC6: =+(S6-T6)*V6-'data 1'!$F$4 -> 24.7185 | AD6: =+(Q6-P6)*(R6-U6)*L6*V6/100 -> -9.2394836 | AE6: =+(Y6*V6-70)+V6*(Z6-IF(D6="UNTUCA",IF(+((W6-3)*2.5+(X6-3)*3.1)>0,+((W6-3)*1.5+(X6-3)*3.1),0),IF(+((W6-3)*1.5+(X6-3)*3.1)>0,+((W6-3)*1.5+(X6-3)*3.1),0))) -> -14.885 | AF6: =(L6-O6)*(R6-U6)*Q6*V6/100 -> 23.93367 | AG6: =+IF(D6="RONALD WILLIAN GARIBAY ESCUDERO",AC6+AD6+AE6+AF6+70,AC6+AD6+AE6+AF6) -> 24.527686 | AH6: =31.1035*L6*Q6*1.1023*K6/100 -> 7.9737349 | AI6: =+((+$AI$2-R6+U6)*L6*Q6*V6)/100 -> 18.856928 | AJ6: =31.1035*1.1023*K6*P6*O6/100 -> 7.2344235 | AL6: 0
A7: IP-784 | C7: 45624 | D7: ZICAMP S.A.C. | E7: {=XLOOKUP(D7,RUC!$B$3:$B$79,RUC!$D$3:$D$79)} -> #N/A | F7: Hernan Mamani | H7: LLAMPO | I7: 8.98 | J7: 16 | K7: =+I7-(I7*(J7/100)) -> 7.5432 | L7: 0.078 | M7: 0.068 | N7: 0.068 | O7: =+ROUND((M7+N7)/2,3) -> 0.068 | P7: 90 | Q7: 85.07 | R7: 2641.85 | S7: =IF((90+ROUNDDOWN(O7,1)*100)<95,95,(90+ROUNDDOWN(O7,1)*100)) -> 95 | U7: 100 | V7: 1.1023 | Y7: 20 | Z7: =IF(IF(D7="UNTUCA",IF(+((W7-3)*1.5+(X7-3)*3.1)>0,+((W7-3)*1.5+(X7-3)*3.1),0),IF(+((W7-3)*1.5+(X7-3)*3.1)>0,+((W7-3)*1.5+(X7-3)*3.1),0))<30,30,IF(D7="UNTUCA",IF(+((W7-3)*1.5+(X7-3)*3.1)>0,+((W7-3)*1.5+(X7-3)*3.1),0),IF(+((W7-3)*1.5+(X7-3)*3.1)>0,+((W7-3)*1.5+(X7-3)*3.1),0))) -> 30 | AA7: =+Y7+Z7 -> 50 | AB7: 0 | AC7: =+(S7-T7)*V7-'data 1'!$F$4 -> 24.7185 | AD7: =+(Q7-P7)*(R7-U7)*L7*V7/100 -> -10.774354 | AE7: =+(Y7*V7-70)+V7*(Z7-IF(D7="UNTUCA",IF(+((W7-3)*2.5+(X7-3)*3.1)>0,+((W7-3)*1.5+(X7-3)*3.1),0),IF(+((W7-3)*1.5+(X7-3)*3.1)>0,+((W7-3)*1.5+(X7-3)*3.1),0))) -> -14.885 | AF7: =(L7-O7)*(R7-U7)*Q7*V7/100 -> 23.835604 | AG7: =+IF(D7="RONALD WILLIAN GARIBAY ESCUDERO",AC7+AD7+AE7+AF7+70,AC7+AD7+AE7+AF7) -> 22.89475 | AH7: =31.1035*L7*Q7*1.1023*K7/100 -> 17.160729 | AI7: =+((+$AI$2-R7+U7)*L7*Q7*V7)/100 -> 20.344635 | AJ7: =31.1035*1.1023*K7*P7*O7/100 -> 15.827638 | AL7: 0
A8: IP-785 | C8: 45624 | D8: ZICAMP S.A.C. | E8: {=XLOOKUP(D8,RUC!$B$3:$B$79,RUC!$D$3:$D$79)} -> #N/A | F8: Hernan Mamani | H8: LLAMPO | I8: 4.48 | J8: 17.5 | K8: =+I8-(I8*(J8/100)) -> 3.696 | L8: 0.084 | M8: 0.074 | N8: 0.074 | O8: =+ROUND((M8+N8)/2,3) -> 0.074 | P8: 90 | Q8: 85.7 | R8: 2641.85 | S8: =IF((90+ROUNDDOWN(O8,1)*100)<95,95,(90+ROUNDDOWN(O8,1)*100)) -> 95 | U8: 100 | V8: 1.1023 | Y8: 20 | Z8: =IF(IF(D8="UNTUCA",IF(+((W8-3)*1.5+(X8-3)*3.1)>0,+((W8-3)*1.5+(X8-3)*3.1),0),IF(+((W8-3)*1.5+(X8-3)*3.1)>0,+((W8-3)*1.5+(X8-3)*3.1),0))<30,30,IF(D8="UNTUCA",IF(+((W8-3)*1.5+(X8-3)*3.1)>0,+((W8-3)*1.5+(X8-3)*3.1),0),IF(+((W8-3)*1.5+(X8-3)*3.1)>0,+((W8-3)*1.5+(X8-3)*3.1),0))) -> 30 | AA8: =+Y8+Z8 -> 50 | AB8: 0 | AC8: =+(S8-T8)*V8-'data 1'!$F$4 -> 24.7185 | AD8: =+(Q8-P8)*(R8-U8)*L8*V8/100 -> -10.120395 | AE8: =+(Y8*V8-70)+V8*(Z8-IF(D8="UNTUCA",IF(+((W8-3)*2.5+(X8-3)*3.1)>0,+((W8-3)*1.5+(X8-3)*3.1),0),IF(+((W8-3)*1.5+(X8-3)*3.1)>0,+((W8-3)*1.5+(X8-3)*3.1),0))) -> -14.885 | AF8: =(L8-O8)*(R8-U8)*Q8*V8/100 -> 24.012122 | AG8: =+IF(D8="RONALD WILLIAN GARIBAY ESCUDERO",AC8+AD8+AE8+AF8+70,AC8+AD8+AE8+AF8) -> 23.725227 | AH8: =31.1035*L8*Q8*1.1023*K8/100 -> 9.1222326 | AI8: =+((+$AI$2-R8+U8)*L8*Q8*V8)/100 -> 22.071862 | AJ8: =31.1035*1.1023*K8*P8*O8/100 -> 8.4394717 | AL8: 0
A9: IP-969 | B9: 45666 | C9: 45649 | D9: SOTOMAYOR CORAZAO WISTHERMUNDO | E9: {=XLOOKUP(D9,RUC!$B$3:$B$79,RUC!$D$3:$D$79)} -> 10416085884 | G9: AGRANEL | H9: MINERAL | I9: 33.74 | J9: 6.1 | K9: =+I9-(I9*(J9/100)) -> 31.68186 | L9: 0.1505 | M9: 0.1407175 | N9: 0.163 | O9: =+ROUND((M9+N9)/2,3) -> 0.152 | P9: 90 | Q9: 89.74 | R9: 2613.8 | S9: 85 | U9: 90 | V9: 1.1023 | Z9: 15 | AA9: =+Y9+Z9 -> 15 | AB9: =+((O9*P9*(R9-U9)/100)-S9-AA9+T9)*V9 -> 270.34551 | AC9: =+(S9-T9)*V9-'data 1'!$F$4 -> 13.6955 | AD9: =+(Q9-P9)*(R9-U9)*L9*V9/100 -> -1.0885906 | AE9: =+(Y9*V9-70)+V9*(Z9-IF(D9="UNTUCA",IF(+((W9-3)*2.5+(X9-3)*3.1)>0,+((W9-3)*1.5+(X9-3)*3.1),0),IF(+((W9-3)*1.5+(X9-3)*3.1)>0,+((W9-3)*1.5+(X9-3)*3.1),0))) -> -53.4655 | AF9: =(L9-O9)*(R9-U9)*Q9*V9/100 -> -3.7448297 | AG9: =+IF(D9="RONALD WILLIAN GARIBAY ESCUDERO",AC9+AD9+AE9+AF9+70,AC9+AD9+AE9+AF9)+70-10 -> 15.39658 | AH9: =31.1035*L9*Q9*1.1023*K9/100 -> 146.70412 | AI9: =+((+$AI$2-R9+U9)*L9*Q9*V9)/100 -> 44.096836 | AJ9: =31.1035*1.1023*K9*P9*O9/100 -> 148.59556 | AL9: =+IF(AB9*K9>0,AB9*K9,0) -> 8565.0487
A10: IP-970 | B10: 45666 | C10: 45649 | D10: SOTOMAYOR CORAZAO WISTHERMUNDO | E10: {=XLOOKUP(D10,RUC!$B$3:$B$79,RUC!$D$3:$D$79)} -> 10416085884 | G10: 26 | H10: MINERAL | I10: 1.5 | J10: 7.45 | K10: =+I10-(I10*(J10/100)) -> 1.38825 | L10: 0.3205 | M10: 0.30768 | N10: 0.355 | O10: =+ROUND((M10+N10)/2,3) -> 0.331 | P10: 90 | Q10: 89.62 | R10: 2613.8 | S10: 100 | U10: 90 | V10: 1.1023 | Z10: 15 | AA10: =+Y10+Z10 -> 15 | AB10: =+((O10*P10*(R10-U10)/100)-S10-AA10+T10)*V10 -> 701.98875 | AC10: =+(S10-T10)*V10-'data 1'!$F$4 -> 30.23 | AD10: =+(Q10-P10)*(R10-U10)*L10*V10/100 -> -3.3881792 | AE10: =+(Y10*V10-70)+V10*(Z10-IF(D10="UNTUCA",IF(+((W10-3)*2.5+(X10-3)*3.1)>0,+((W10-3)*1.5+(X10-3)*3.1),0),IF(+((W10-3)*1.5+(X10-3)*3.1)>0,+((W10-3)*1.5+(X10-3)*3.1),0))) -> -53.4655 | AF10: =(L10-O10)*(R10-U10)*Q10*V10/100 -> -26.178755 | AG10: =+IF(D10="RONALD WILLIAN GARIBAY ESCUDERO",AC10+AD10+AE10+AF10+70,AC10+AD10+AE10+AF10)+70-10 -> 7.1975662 | AH10: =31.1035*L10*Q10*1.1023*K10/100 -> 13.671297 | AI10: =+((+$AI$2-R10+U10)*L10*Q10*V10)/100 -> 93.781643 | AJ10: =31.1035*1.1023*K10*P10*O10/100 -> 14.179054 | AL10: =+IF(AB10*K10>0,AB10*K10,0) -> 974.53589
A11: IP-973 | B11: 45657 | C11: 45649 | D11: SOTOMAYOR CORAZAO WISTHERMUNDO | E11: {=XLOOKUP(D11,RUC!$B$3:$B$79,RUC!$D$3:$D$79)} -> 10416085884 | G11: AGRANEL | H11: MINERAL | I11: 26.91 | J11: 3.9 | K11: =+I11-(I11*(J11/100)) -> 25.86051 | L11: 0.1025 | M11: 0.097 | N11: 0.108 | O11: =+ROUND((M11+N11)/2,3) -> 0.103 | P11: 80 | Q11: 89.39 | R11: 2613.8 | S11: 110 | U11: 90 | V11: 1.1023 | Z11: =IF(IF(D11="UNTUCA",IF(+((W11-3)*1.5+(X11-3)*3.1)>0,+((W11-3)*1.5+(X11-3)*3.1),0),IF(+((W11-3)*1.5+(X11-3)*3.1)>0,+((W11-3)*1.5+(X11-3)*3.1),0))<30,30,IF(D11="UNTUCA",IF(+((W11-3)*1.5+(X11-3)*3.1)>0,+((W11-3)*1.5+(X11-3)*3.1),0),IF(+((W11-3)*1.5+(X11-3)*3.1)>0,+((W11-3)*1.5+(X11-3)*3.1),0))) -> 30 | AA11: =+Y11+Z11 -> 30 | AB11: =+((O11*P11*(R11-U11)/100)-S11-AA11+T11)*V11 -> 74.913543 | AC11: =+(S11-T11)*V11-'data 1'!$F$4 -> 41.253 | AD11: =+(Q11-P11)*(R11-U11)*L11*V11/100 -> 26.775908 | AE11: =+(Y11*V11-70)+V11*(Z11-IF(D11="UNTUCA",IF(+((W11-3)*2.5+(X11-3)*3.1)>0,+((W11-3)*1.5+(X11-3)*3.1),0),IF(+((W11-3)*1.5+(X11-3)*3.1)>0,+((W11-3)*1.5+(X11-3)*3.1),0))) -> -36.931 | AF11: =(L11-O11)*(R11-U11)*Q11*V11/100 -> -1.2434081 | AG11: =+IF(D11="RONALD WILLIAN GARIBAY ESCUDERO",AC11+AD11+AE11+AF11+70,AC11+AD11+AE11+AF11)+70-53 -> 46.8545 | AH11: =31.1035*L11*Q11*1.1023*K11/100 -> 81.23795 | AI11: =+((+$AI$2-R11+U11)*L11*Q11*V11)/100 -> 29.915596 | AJ11: =31.1035*1.1023*K11*P11*O11/100 -> 73.05894 | AL11: =+IF(AB11*K11>0,AB11*K11,0) -> 1937.3024
A12: IP-1004 | B12: 45657 | C12: 45654 | D12: RONALD WILLIAN GARIBAY ESCUDERO | E12: {=XLOOKUP(D12,RUC!$B$3:$B$79,RUC!$D$3:$D$79)} -> #N/A | G12: AGRANEL | H12: MINERAL | I12: 9.58 | J12: 1.2 | K12: =+I12-(I12*(J12/100)) -> 9.46504 | L12: 0.414 | M12: 0.397 | N12: 0.456 | O12: =+ROUND((M12+N12)/2,3) -> 0.427 | P12: 90 | Q12: 89.79 | R12: 2615.95 | S12: 120 | U12: 100 | V12: 1.1023 | Y12: 0 | Z12: =IF(IF(D12="UNTUCA",IF(+((W12-3)*1.5+(X12-3)*3.1)>0,+((W12-3)*1.5+(X12-3)*3.1),0),IF(+((W12-3)*1.5+(X12-3)*3.1)>0,+((W12-3)*1.5+(X12-3)*3.1),0))<30,30,IF(D12="UNTUCA",IF(+((W12-3)*1.5+(X12-3)*3.1)>0,+((W12-3)*1.5+(X12-3)*3.1),0),IF(+((W12-3)*1.5+(X12-3)*3.1)>0,+((W12-3)*1.5+(X12-3)*3.1),0))) -> 30 | AA12: =+Y12+Z12 -> 30 | AB12: =+((O12*P12*(R12-U12)/100)-S12-AA12+T12)*V12 -> 900.44637 | AC12: =+(S12-T12)*V12-'data 1'!$F$4 -> 52.276 | AD12: =+(Q12-P12)*(R12-U12)*L12*V12/100 -> -2.4111346 | AE12: =+(Y12*V12-70)+V12*(Z12-IF(D12="UNTUCA",IF(+((W12-3)*2.5+(X12-3)*3.1)>0,+((W12-3)*1.5+(X12-3)*3.1),0),IF(+((W12-3)*1.5+(X12-3)*3.1)>0,+((W12-3)*1.5+(X12-3)*3.1),0))) -> -36.931 | AF12: =(L12-O12)*(R12-U12)*Q12*V12/100 -> -32.372269 | AG12: =+IF(D12="RONALD WILLIAN GARIBAY ESCUDERO",AC12+AD12+AE12+AF12+70,AC12+AD12+AE12+AF12) -> 50.561597 | AH12: =31.1035*L12*Q12*1.1023*K12/100 -> 120.63125 | AI12: =+((+$AI$2-R12+U12)*L12*Q12*V12)/100 -> 124.58711 | AJ12: =31.1035*1.1023*K12*P12*O12/100 -> 124.71018 | AL12: =+IF(AB12*K12>0,AB12*K12,0) -> 8522.7609
A13: IP-1006 | B13: 45660 | C13: 45655 | D13: QUISPE MARTINEZ IZEQUIEL | E13: {=XLOOKUP(D13,RUC!$B$3:$B$79,RUC!$D$3:$D$79)} -> 10457401928 | F13: Dario Sanchez | G13: 80 | H13: MINERAL | I13: 33.91 | J13: 15.4 | K13: =+I13-(I13*(J13/100)) -> 28.68786 | L13: 0.585 | M13: 0.561 | N13: 0.598 | O13: =+ROUND((M13+N13)/2,3) -> 0.58 | P13: 90 | Q13: 89.66 | R13: 2615.95 | S13: 130 | U13: 100 | V13: 1.1023 | Z13: =IF(IF(D13="UNTUCA",IF(+((W13-3)*1.5+(X13-3)*3.1)>0,+((W13-3)*1.5+(X13-3)*3.1),0),IF(+((W13-3)*1.5+(X13-3)*3.1)>0,+((W13-3)*1.5+(X13-3)*3.1),0))<30,30,IF(D13="UNTUCA",IF(+((W13-3)*1.5+(X13-3)*3.1)>0,+((W13-3)*1.5+(X13-3)*3.1),0),IF(+((W13-3)*1.5+(X13-3)*3.1)>0,+((W13-3)*1.5+(X13-3)*3.1),0))) -> 30 | AA13: =+Y13+Z13 -> 30 | AB13: =+((O13*P13*(R13-U13)/100)-S13-AA13+T13)*V13 -> 1271.3111 | AC13: =+(S13-T13)*V13-'data 1'!$F$4 -> 63.299 | AD13: =+(Q13-P13)*(R13-U13)*L13*V13/100 -> -5.5161567 | AE13: =+(Y13*V13-70)+V13*(Z13-IF(D13="UNTUCA",IF(+((W13-3)*2.5+(X13-3)*3.1)>0,+((W13-3)*1.5+(X13-3)*3.1),0),IF(+((W13-3)*1.5+(X13-3)*3.1)>0,+((W13-3)*1.5+(X13-3)*3.1),0))) -> -36.931 | AF13: =(L13-O13)*(R13-U13)*Q13*V13/100 -> 12.432846 | AG13: =+IF(D13="RONALD WILLIAN GARIBAY ESCUDERO",AC13+AD13+AE13+AF13+70,AC13+AD13+AE13+AF13) -> 33.284689 | AH13: =31.1035*L13*Q13*1.1023*K13/100 -> 515.8956 | AI13: =+((+$AI$2-R13+U13)*L13*Q13*V13)/100 -> 175.79212 | AJ13: =31.1035*1.1023*K13*P13*O13/100 -> 513.42584 | AL13: =+IF(AB13*K13>0,AB13*K13,0) -> 36471.196
A14: IP-1007 | B14: 45660 | C14: 45655 | D14: QUISPE MARTINEZ IZEQUIEL | E14: {=XLOOKUP(D14,RUC!$B$3:$B$79,RUC!$D$3:$D$79)} -> 10457401928 | F14: Dario Sanchez | G14: 90 | H14: MINERAL | I14: 34.66 | J14: 16.35 | K14: =+I14-(I14*(J14/100)) -> 28.99309 | L14: 0.576 | M14: 0.553 | N14: 0.574 | O14: =+ROUND((M14+N14)/2,3) -> 0.564 | P14: 90 | Q14: 89.71 | R14: 2615.95 | S14: 130 | U14: 100 | V14: 1.1023 | Z14: =IF(IF(D14="UNTUCA",IF(+((W14-3)*1.5+(X14-3)*3.1)>0,+((W14-3)*1.5+(X14-3)*3.1),0),IF(+((W14-3)*1.5+(X14-3)*3.1)>0,+((W14-3)*1.5+(X14-3)*3.1),0))<30,30,IF(D14="UNTUCA",IF(+((W14-3)*1.5+(X14-3)*3.1)>0,+((W14-3)*1.5+(X14-3)*3.1),0),IF(+((W14-3)*1.5+(X14-3)*3.1)>0,+((W14-3)*1.5+(X14-3)*3.1),0))) -> 30 | AA14: =+Y14+Z14 -> 30 | AB14: =+((O14*P14*(R14-U14)/100)-S14-AA14+T14)*V14 -> 1231.3752 | AC14: =+(S14-T14)*V14-'data 1'!$F$4 -> 63.299 | AD14: =+(Q14-P14)*(R14-U14)*L14*V14/100 -> -4.6325732 | AE14: =+(Y14*V14-70)+V14*(Z14-IF(D14="UNTUCA",IF(+((W14-3)*2.5+(X14-3)*3.1)>0,+((W14-3)*1.5+(X14-3)*3.1),0),IF(+((W14-3)*1.5+(X14-3)*3.1)>0,+((W14-3)*1.5+(X14-3)*3.1),0))) -> -36.931 | AF14: =(L14-O14)*(R14-U14)*Q14*V14/100 -> 29.85547 | AG14: =+IF(D14="RONALD WILLIAN GARIBAY ESCUDERO",AC14+AD14+AE14+AF14+70,AC14+AD14+AE14+AF14) -> 51.590897 | AH14: =31.1035*L14*Q14*1.1023*K14/100 -> 513.64955 | AI14: =+((+$AI$2-R14+U14)*L14*Q14*V14)/100 -> 173.18416 | AJ14: =31.1035*1.1023*K14*P14*O14/100 -> 504.57437 | AL14: =+IF(AB14*K14>0,AB14*K14,0) -> 35701.371
A15: IP-1008 | B15: 45660 | C15: 45655 | D15: INVERSIONES Y SERVICIOS MULTIPLES SANTA LUCIA E.I.R.L | E15: {=XLOOKUP(D15,RUC!$B$3:$B$79,RUC!$D$3:$D$79)} -> 20610873309 | G15: 144 | H15: MINERAL | I15: 11.96 | J15: 1 | K15: =+I15-(I15*(J15/100)) -> 11.8404 | L15: 0.559 | M15: 0.537 | N15: 0.647 | O15: =+ROUND((M15+N15)/2,3) -> 0.592 | P15: 90 | Q15: 89.46 | R15: 2615.95 | S15: =IF((90+ROUNDDOWN(O15,1)*100)<95,95,(90+ROUNDDOWN(O15,1)*100)) -> 140 | U15: 120 | V15: 1.1023 | Y15: 20 | Z15: =IF(IF(D15="UNTUCA",IF(+((W15-3)*1.5+(X15-3)*3.1)>0,+((W15-3)*1.5+(X15-3)*3.1),0),IF(+((W15-3)*1.5+(X15-3)*3.1)>0,+((W15-3)*1.5+(X15-3)*3.1),0))<30,30,IF(D15="UNTUCA",IF(+((W15-3)*1.5+(X15-3)*3.1)>0,+((W15-3)*1.5+(X15-3)*3.1),0),IF(+((W15-3)*1.5+(X15-3)*3.1)>0,+((W15-3)*1.5+(X15-3)*3.1),0))) -> 30 | AA15: =+Y15+Z15 -> 50 | AB15: =+((O15*P15*(R15-U15)/100)-S15-AA15+T15)*V15 -> 1256.448 | AC15: =+(S15-T15)*V15-'data 1'!$F$4 -> 74.322 | AD15: =+(Q15-P15)*(R15-U15)*L15*V15/100 -> -8.305031 | AE15: =+(Y15*V15-70)+V15*(Z15-IF(D15="UNTUCA",IF(+((W15-3)*2.5+(X15-3)*3.1)>0,+((W15-3)*1.5+(X15-3)*3.1),0),IF(+((W15-3)*1.5+(X15-3)*3.1)>0,+((W15-3)*1.5+(X15-3)*3.1),0))) -> -14.885 | AF15: =(L15-O15)*(R15-U15)*Q15*V15/100 -> -81.222906 | AG15: =+IF(D15="RONALD WILLIAN GARIBAY ESCUDERO",AC15+AD15+AE15+AF15+70,AC15+AD15+AE15+AF15)+70-53 -> -13.090937 | AH15: =31.1035*L15*Q15*1.1023*K15/100 -> 203.0094 | AI15: =+((+$AI$2-R15+U15)*L15*Q15*V15)/100 -> 178.62923 | AJ15: =31.1035*1.1023*K15*P15*O15/100 -> 216.2916 | AL15: =+IF(AB15*K15>0,AB15*K15,0) -> 14876.847
A16: IP-1009 | B16: 45657 | C16: 45655 | D16: RONALD WILLIAN GARIBAY ESCUDERO | E16: {=XLOOKUP(D16,RUC!$B$3:$B$79,RUC!$D$3:$D$79)} -> #N/A | G16: 94 | H16: LLAMPO | I16: 7.16 | J16: 1.5 | K16: =+I16-(I16*(J16/100)) -> 7.0526 | L16: 0.389 | M16: 0.373 | N16: 0.459 | O16: =+ROUND((M16+N16)/2,3) -> 0.416 | P16: 90 | Q16: 89.84 | R16: 2615.95 | S16: 120 | U16: 100 | V16: 1.1023 | Y16: 0 | Z16: =IF(IF(D16="UNTUCA",IF(+((W16-3)*1.5+(X16-3)*3.1)>0,+((W16-3)*1.5+(X16-3)*3.1),0),IF(+((W16-3)*1.5+(X16-3)*3.1)>0,+((W16-3)*1.5+(X16-3)*3.1),0))<30,30,IF(D16="UNTUCA",IF(+((W16-3)*1.5+(X16-3)*3.1)>0,+((W16-3)*1.5+(X16-3)*3.1),0),IF(+((W16-3)*1.5+(X16-3)*3.1)>0,+((W16-3)*1.5+(X16-3)*3.1),0))) -> 30 | AA16: =+Y16+Z16 -> 30 | AB16: =+((O16*P16*(R16-U16)/100)-S16-AA16+T16)*V16 -> 872.99038 | AC16: =+(S16-T16)*V16-'data 1'!$F$4 -> 52.276 | AD16: =+(Q16-P16)*(R16-U16)*L16*V16/100 -> -1.7261216 | AE16: =+(Y16*V16-70)+V16*(Z16-IF(D16="UNTUCA",IF(+((W16-3)*2.5+(X16-3)*3.1)>0,+((W16-3)*1.5+(X16-3)*3.1),0),IF(+((W16-3)*1.5+(X16-3)*3.1)>0,+((W16-3)*1.5+(X16-3)*3.1),0))) -> -36.931 | AF16: =(L16-O16)*(R16-U16)*Q16*V16/100 -> -67.272152 | AG16: =+IF(D16="RONALD WILLIAN GARIBAY ESCUDERO",AC16+AD16+AE16+AF16+70,AC16+AD16+AE16+AF16) -> 16.346726 | AH16: =31.1035*L16*Q16*1.1023*K16/100 -> 84.504078 | AI16: =+((+$AI$2-R16+U16)*L16*Q16*V16)/100 -> 117.12893 | AJ16: =31.1035*1.1023*K16*P16*O16/100 -> 90.530342 | AL16: =+IF(AB16*K16>0,AB16*K16,0) -> 6156.852
A17: IP-1010 | B17: 45661 | C17: 45655 | D17: INVERSIONES Y SERVICIOS MULTIPLES SANTA LUCIA E.I.R.L | E17: {=XLOOKUP(D17,RUC!$B$3:$B$79,RUC!$D$3:$D$79)} -> 20610873309 | G17: 80 | H17: MINERAL | I17: 7.66 | J17: 1.6 | K17: =+I17-(I17*(J17/100)) -> 7.53744 | L17: 0.199 | M17: 0.189 | N17: 0.189 | O17: =+ROUND((M17+N17)/2,3) -> 0.189 | P17: 90 | Q17: 89.77 | R17: 2615.95 | S17: =IF((90+ROUNDDOWN(O17,1)*100)<95,95,(90+ROUNDDOWN(O17,1)*100)) -> 100 | U17: 120 | V17: 1.1023 | Y17: 10 | Z17: =IF(IF(D17="UNTUCA",IF(+((W17-3)*1.5+(X17-3)*3.1)>0,+((W17-3)*1.5+(X17-3)*3.1),0),IF(+((W17-3)*1.5+(X17-3)*3.1)>0,+((W17-3)*1.5+(X17-3)*3.1),0))<30,30,IF(D17="UNTUCA",IF(+((W17-3)*1.5+(X17-3)*3.1)>0,+((W17-3)*1.5+(X17-3)*3.1),0),IF(+((W17-3)*1.5+(X17-3)*3.1)>0,+((W17-3)*1.5+(X17-3)*3.1),0))) -> 30 | AA17: =+Y17+Z17 -> 40 | AB17: =+((O17*P17*(R17-U17)/100)-S17-AA17+T17)*V17 -> 313.67169 | AC17: =+(S17-T17)*V17-'data 1'!$F$4 -> 30.23 | AD17: =+(Q17-P17)*(R17-U17)*L17*V17/100 -> -1.2592635 | AE17: =+(Y17*V17-70)+V17*(Z17-IF(D17="UNTUCA",IF(+((W17-3)*2.5+(X17-3)*3.1)>0,+((W17-3)*1.5+(X17-3)*3.1),0),IF(+((W17-3)*1.5+(X17-3)*3.1)>0,+((W17-3)*1.5+(X17-3)*3.1),0))) -> -25.908 | AF17: =(L17-O17)*(R17-U17)*Q17*V17/100 -> 24.698292 | AG17: =+IF(D17="RONALD WILLIAN GARIBAY ESCUDERO",AC17+AD17+AE17+AF17+70,AC17+AD17+AE17+AF17)+70-53 -> 44.761028 | AH17: =31.1035*L17*Q17*1.1023*K17/100 -> 46.165468 | AI17: =+((+$AI$2-R17+U17)*L17*Q17*V17)/100 -> 63.811086 | AJ17: =31.1035*1.1023*K17*P17*O17/100 -> 43.957932 | AL17: =+IF(AB17*K17>0,AB17*K17,0) -> 2364.2816
A18: IP-1011 | B18: 45660 | C18: 45655 | D18: EMPRESA MINERA MARKATA CAS S.A.C. | E18: {=XLOOKUP(D18,RUC!$B$3:$B$79,RUC!$D$3:$D$79)} -> 20606526599 | G18: 110 | H18: MINERAL | I18: 9.23 | J18: 1.1 | K18: =+I18-(I18*(J18/100)) -> 9.12847 | L18: 0.334 | M18: 0.32 | N18: 0.32 | O18: =+ROUND((M18+N18)/2,3) -> 0.32 | P18: 90 | Q18: 89.56 | R18: 2615.95 | S18: =IF((90+ROUNDDOWN(O18,1)*100)<95,95,(90+ROUNDDOWN(O18,1)*100)) -> 120 | U18: 120 | V18: 1.1023 | Y18: 20 | Z18: =IF(IF(D18="UNTUCA",IF(+((W18-3)*1.5+(X18-3)*3.1)>0,+((W18-3)*1.5+(X18-3)*3.1),0),IF(+((W18-3)*1.5+(X18-3)*3.1)>0,+((W18-3)*1.5+(X18-3)*3.1),0))<30,30,IF(D18="UNTUCA",IF(+((W18-3)*1.5+(X18-3)*3.1)>0,+((W18-3)*1.5+(X18-3)*3.1),0),IF(+((W18-3)*1.5+(X18-3)*3.1)>0,+((W18-3)*1.5+(X18-3)*3.1),0))) -> 30 | AA18: =+Y18+Z18 -> 50 | AB18: =+((O18*P18*(R18-U18)/100)-S18-AA18+T18)*V18 -> 604.97928 | AC18: =+(S18-T18)*V18-'data 1'!$F$4 -> 52.276 | AD18: =+(Q18-P18)*(R18-U18)*L18*V18/100 -> -4.0432894 | AE18: =+(Y18*V18-70)+V18*(Z18-IF(D18="UNTUCA",IF(+((W18-3)*2.5+(X18-3)*3.1)>0,+((W18-3)*1.5+(X18-3)*3.1),0),IF(+((W18-3)*1.5+(X18-3)*3.1)>0,+((W18-3)*1.5+(X18-3)*3.1),0))) -> -14.885 | AF18: =(L18-O18)*(R18-U18)*Q18*V18/100 -> 34.49672 | AG18: =+IF(D18="RONALD WILLIAN GARIBAY ESCUDERO",AC18+AD18+AE18+AF18+70,AC18+AD18+AE18+AF18)+70-53 -> 84.844431 | AH18: =31.1035*L18*Q18*1.1023*K18/100 -> 93.619779 | AI18: =+((+$AI$2-R18+U18)*L18*Q18*V18)/100 -> 106.84947 | AJ18: =31.1035*1.1023*K18*P18*O18/100 -> 90.136263 | AL18: =+IF(AB18*K18>0,AB18*K18,0) -> 5522.5352
A19: IP-1012 | B19: 45660 | C19: 45656 | D19: LLASA YUCRA YOLANDA | E19: {=XLOOKUP(D19,RUC!$B$3:$B$79,RUC!$D$3:$D$79)} -> #N/A | G19: 12 | H19: MINERAL | I19: 1.07 | J19: 1.3 | K19: =+I19-(I19*(J19/100)) -> 1.05609 | L19: 0.234 | M19: 0.224 | N19: 0.224 | O19: =+ROUND((M19+N19)/2,3) -> 0.224 | P19: 90 | Q19: 89.56 | R19: 2609.1 | S19: =IF((90+ROUNDDOWN(O19,1)*100)<95,95,(90+ROUNDDOWN(O19,1)*100)) -> 110 | U19: 110 | V19: 1.1023 | Y19: 20 | Z19: =IF(IF(D19="UNTUCA",IF(+((W19-3)*1.5+(X19-3)*3.1)>0,+((W19-3)*1.5+(X19-3)*3.1),0),IF(+((W19-3)*1.5+(X19-3)*3.1)>0,+((W19-3)*1.5+(X19-3)*3.1),0))<30,30,IF(D19="UNTUCA",IF(+((W19-3)*1.5+(X19-3)*3.1)>0,+((W19-3)*1.5+(X19-3)*3.1),0),IF(+((W19-3)*1.5+(X19-3)*3.1)>0,+((W19-3)*1.5+(X19-3)*3.1),0))) -> 30 | AA19: =+Y19+Z19 -> 50 | AB19: =+((O19*P19*(R19-U19)/100)-S19-AA19+T19)*V19 -> 378.9912 | AC19: =+(S19-T19)*V19-'data 1'!$F$4 -> 41.253 | AD19: =+(Q19-P19)*(R19-U19)*L19*V19/100 -> -2.8362988 | AE19: =+(Y19*V19-70)+V19*(Z19-IF(D19="UNTUCA",IF(+((W19-3)*2.5+(X19-3)*3.1)>0,+((W19-3)*1.5+(X19-3)*3.1),0),IF(+((W19-3)*1.5+(X19-3)*3.1)>0,+((W19-3)*1.5+(X19-3)*3.1),0))) -> -14.885 | AF19: =(L19-O19)*(R19-U19)*Q19*V19/100 -> 24.671612 | AG19: =+IF(D19="RONALD WILLIAN GARIBAY ESCUDERO",AC19+AD19+AE19+AF19+70,AC19+AD19+AE19+AF19)+70-53 -> 65.203313 | AH19: =31.1035*L19*Q19*1.1023*K19/100 -> 7.5882205 | AI19: =+((+$AI$2-R19+U19)*L19*Q19*V19)/100 -> 74.130933 | AJ19: =31.1035*1.1023*K19*P19*O19/100 -> 7.2996246 | AL19: =+IF(AB19*K19>0,AB19*K19,0) -> 400.24881
A20: IP-1013 | B20: 45660 | C20: 45656 | D20: LLASA YUCRA YOLANDA | E20: {=XLOOKUP(D20,RUC!$B$3:$B$79,RUC!$D$3:$D$79)} -> #N/A | G20: 22 | H20: MINERAL | I20: 1.92 | J20: 1.4 | K20: =+I20-(I20*(J20/100)) -> 1.89312 | L20: 0.158 | M20: 0.148 | N20: 0.148 | O20: =+ROUND((M20+N20)/2,3) -> 0.148 | P20: 90 | Q20: 89.79 | R20: 2609.1 | S20: =IF((90+ROUNDDOWN(O20,1)*100)<95,95,(90+ROUNDDOWN(O20,1)*100)) -> 100 | U20: 110 | V20: 1.1023 | Y20: 20 | Z20: =IF(IF(D20="UNTUCA",IF(+((W20-3)*1.5+(X20-3)*3.1)>0,+((W20-3)*1.5+(X20-3)*3.1),0),IF(+((W20-3)*1.5+(X20-3)*3.1)>0,+((W20-3)*1.5+(X20-3)*3.1),0))<30,30,IF(D20="UNTUCA",IF(+((W20-3)*1.5+(X20-3)*3.1)>0,+((W20-3)*1.5+(X20-3)*3.1),0),IF(+((W20-3)*1.5+(X20-3)*3.1)>0,+((W20-3)*1.5+(X20-3)*3.1),0))) -> 30 | AA20: =+Y20+Z20 -> 50 | AB20: =+((O20*P20*(R20-U20)/100)-S20-AA20+T20)*V20 -> 201.58876 | AC20: =+(S20-T20)*V20-'data 1'!$F$4 -> 30.23 | AD20: =+(Q20-P20)*(R20-U20)*L20*V20/100 -> -0.91402868 | AE20: =+(Y20*V20-70)+V20*(Z20-IF(D20="UNTUCA",IF(+((W20-3)*2.5+(X20-3)*3.1)>0,+((W20-3)*1.5+(X20-3)*3.1),0),IF(+((W20-3)*1.5+(X20-3)*3.1)>0,+((W20-3)*1.5+(X20-3)*3.1),0))) -> -14.885 | AF20: =(L20-O20)*(R20-U20)*Q20*V20/100 -> 24.734971 | AG20: =+IF(D20="RONALD WILLIAN GARIBAY ESCUDERO",AC20+AD20+AE20+AF20+70,AC20+AD20+AE20+AF20)+70-53 -> 56.165943 | AH20: =31.1035*L20*Q20*1.1023*K20/100 -> 9.2081476 | AI20: =+((+$AI$2-R20+U20)*L20*Q20*V20)/100 -> 50.182765 | AJ20: =31.1035*1.1023*K20*P20*O20/100 -> 8.6455263 | AL20: =+IF(AB20*K20>0,AB20*K20,0) -> 381.63171
A21: IP-1014 | B21: 45660 | C21: 45656 | D21: LLASA YUCRA YOLANDA | E21: {=XLOOKUP(D21,RUC!$B$3:$B$79,RUC!$D$3:$D$79)} -> #N/A | G21: 22 | H21: MINERAL | I21: 1.97 | J21: 1.5 | K21: =+I21-(I21*(J21/100)) -> 1.94045 | L21: 0.171 | M21: 0.161 | N21: 0.161 | O21: =+ROUND((M21+N21)/2,3) -> 0.161 | P21: 90 | Q21: 89.72 | R21: 2609.1 | S21: =IF((90+ROUNDDOWN(O21,1)*100)<95,95,(90+ROUNDDOWN(O21,1)*100)) -> 100 | U21: 110 | V21: 1.1023 | Y21: 20 | Z21: =IF(IF(D21="UNTUCA",IF(+((W21-3)*1.5+(X21-3)*3.1)>0,+((W21-3)*1.5+(X21-3)*3.1),0),IF(+((W21-3)*1.5+(X21-3)*3.1)>0,+((W21-3)*1.5+(X21-3)*3.1),0))<30,30,IF(D21="UNTUCA",IF(+((W21-3)*1.5+(X21-3)*3.1)>0,+((W21-3)*1.5+(X21-3)*3.1),0),IF(+((W21-3)*1.5+(X21-3)*3.1)>0,+((W21-3)*1.5+(X21-3)*3.1),0))) -> 30 | AA21: =+Y21+Z21 -> 50 | AB21: =+((O21*P21*(R21-U21)/100)-S21-AA21+T21)*V21 -> 233.81942 | AC21: =+(S21-T21)*V21-'data 1'!$F$4 -> 30.23 | AD21: =+(Q21-P21)*(R21-U21)*L21*V21/100 -> -1.3189781 | AE21: =+(Y21*V21-70)+V21*(Z21-IF(D21="UNTUCA",IF(+((W21-3)*2.5+(X21-3)*3.1)>0,+((W21-3)*1.5+(X21-3)*3.1),0),IF(+((W21-3)*1.5+(X21-3)*3.1)>0,+((W21-3)*1.5+(X21-3)*3.1),0))) -> -14.885 | AF21: =(L21-O21)*(R21-U21)*Q21*V21/100 -> 24.715688 | AG21: =+IF(D21="RONALD WILLIAN GARIBAY ESCUDERO",AC21+AD21+AE21+AF21+70,AC21+AD21+AE21+AF21)+70-53 -> 55.74171 | AH21: =31.1035*L21*Q21*1.1023*K21/100 -> 10.206971 | AI21: =+((+$AI$2-R21+U21)*L21*Q21*V21)/100 -> 54.269385 | AJ21: =31.1035*1.1023*K21*P21*O21/100 -> 9.6400639 | AL21: =+IF(AB21*K21>0,AB21*K21,0) -> 453.7149
A22: IP-1015 | B22: 45664 | C22: 45656 | D22: GRUPO EL CAZADOR GOLD E.I.R.L | E22: {=XLOOKUP(D22,RUC!$B$3:$B$79,RUC!$D$3:$D$79)} -> 20606094010 | G22: 30 | H22: MINERAL | I22: 2.66 | J22: 1.6 | K22: =+I22-(I22*(J22/100)) -> 2.61744 | L22: 0.157 | M22: 0.147 | N22: 0.188 | O22: =+ROUND((M22+N22)/2,3) -> 0.168 | P22: 90 | Q22: 89.79 | R22: 2609.1 | S22: =IF((90+ROUNDDOWN(O22,1)*100)<95,95,(90+ROUNDDOWN(O22,1)*100)) -> 100 | U22: 120 | V22: 1.1023 | Y22: 20 | Z22: =IF(IF(D22="UNTUCA",IF(+((W22-3)*1.5+(X22-3)*3.1)>0,+((W22-3)*1.5+(X22-3)*3.1),0),IF(+((W22-3)*1.5+(X22-3)*3.1)>0,+((W22-3)*1.5+(X22-3)*3.1),0))<30,30,IF(D22="UNTUCA",IF(+((W22-3)*1.5+(X22-3)*3.1)>0,+((W22-3)*1.5+(X22-3)*3.1),0),IF(+((W22-3)*1.5+(X22-3)*3.1)>0,+((W22-3)*1.5+(X22-3)*3.1),0))) -> 30 | AA22: =+Y22+Z22 -> 50 | AB22: =+((O22*P22*(R22-U22)/100)-S22-AA22+T22)*V22 -> 249.50772 | AC22: =+(S22-T22)*V22-'data 1'!$F$4 -> 30.23 | AD22: =+(Q22-P22)*(R22-U22)*L22*V22/100 -> -0.90460941 | AE22: =+(Y22*V22-70)+V22*(Z22-IF(D22="UNTUCA",IF(+((W22-3)*2.5+(X22-3)*3.1)>0,+((W22-3)*1.5+(X22-3)*3.1),0),IF(+((W22-3)*1.5+(X22-3)*3.1)>0,+((W22-3)*1.5+(X22-3)*3.1),0))) -> -14.885 | AF22: =(L22-O22)*(R22-U22)*Q22*V22/100 -> -27.099596 | AG22: =+IF(D22="RONALD WILLIAN GARIBAY ESCUDERO",AC22+AD22+AE22+AF22+70,AC22+AD22+AE22+AF22)+70-53 -> 4.3407951 | AH22: =31.1035*L22*Q22*1.1023*K22/100 -> 12.650667 | AI22: =+((+$AI$2-R22+U22)*L22*Q22*V22)/100 -> 51.419068 | AJ22: =31.1035*1.1023*K22*P22*O22/100 -> 13.56868 | AL22: =+IF(AB22*K22>0,AB22*K22,0) -> 653.07149
A23: IP-1016 | B23: 45660 | C23: 45656 | D23: EMPRESA MINERA MARKATA CAS S.A.C. | E23: {=XLOOKUP(D23,RUC!$B$3:$B$79,RUC!$D$3:$D$79)} -> 20606526599 | G23: 65 | H23: MINERAL | I23: 5.03 | J23: 1.9 | K23: =+I23-(I23*(J23/100)) -> 4.93443 | L23: 0.278 | M23: 0.266 | N23: 0.266 | O23: =+ROUND((M23+N23)/2,3) -> 0.266 | P23: 90 | Q23: 89.82 | R23: 2609.1 | S23: =IF((90+ROUNDDOWN(O23,1)*100)<95,95,(90+ROUNDDOWN(O23,1)*100)) -> 110 | U23: 120 | V23: 1.1023 | Y23: 20 | Z23: =IF(IF(D23="UNTUCA",IF(+((W23-3)*1.5+(X23-3)*3.1)>0,+((W23-3)*1.5+(X23-3)*3.1),0),IF(+((W23-3)*1.5+(X23-3)*3.1)>0,+((W23-3)*1.5+(X23-3)*3.1),0))<30,30,IF(D23="UNTUCA",IF(+((W23-3)*1.5+(X23-3)*3.1)>0,+((W23-3)*1.5+(X23-3)*3.1),0),IF(+((W23-3)*1.5+(X23-3)*3.1)>0,+((W23-3)*1.5+(X23-3)*3.1),0))) -> 30 | AA23: =+Y23+Z23 -> 50 | AB23: =+((O23*P23*(R23-U23)/100)-S23-AA23+T23)*V23 -> 480.48214 | AC23: =+(S23-T23)*V23-'data 1'!$F$4 -> 41.253 | AD23: =+(Q23-P23)*(R23-U23)*L23*V23/100 -> -1.372965 | AE23: =+(Y23*V23-70)+V23*(Z23-IF(D23="UNTUCA",IF(+((W23-3)*2.5+(X23-3)*3.1)>0,+((W23-3)*1.5+(X23-3)*3.1),0),IF(+((W23-3)*1.5+(X23-3)*3.1)>0,+((W23-3)*1.5+(X23-3)*3.1),0))) -> -14.885 | AF23: =(L23-O23)*(R23-U23)*Q23*V23/100 -> 29.573073 | AG23: =+IF(D23="RONALD WILLIAN GARIBAY ESCUDERO",AC23+AD23+AE23+AF23+70,AC23+AD23+AE23+AF23)+70-53 -> 71.568108 | AH23: =31.1035*L23*Q23*1.1023*K23/100 -> 42.243891 | AI23: =+((+$AI$2-R23+U23)*L23*Q23*V23)/100 -> 91.078196 | AJ23: =31.1035*1.1023*K23*P23*O23/100 -> 40.501416 | AL23: =+IF(AB23*K23>0,AB23*K23,0) -> 2370.9055
A24: IP-1017 | B24: 45663 | C24: 45657 | D24: METAL EXTRACTION COMPANY S.A.C. | E24: {=XLOOKUP(D24,RUC!$B$3:$B$79,RUC!$D$3:$D$79)} -> 20606527439 | G24: 94 | H24: M.LLAMPO | I24: 10.48 | J24: 1.1 | K24: =+I24-(I24*(J24/100)) -> 10.36472 | L24: 0.072 | M24: 0.062 | N24: 0.062 | O24: =+ROUND((M24+N24)/2,3) -> 0.062 | P24: 90 | Q24: 87.8 | R24: 2609.1 | S24: =IF((90+ROUNDDOWN(O24,1)*100)<95,95,(90+ROUNDDOWN(O24,1)*100)) -> 95 | U24: 120 | V24: 1.1023 | Y24: 20 | Z24: =IF(IF(D24="UNTUCA",IF(+((W24-3)*1.5+(X24-3)*3.1)>0,+((W24-3)*1.5+(X24-3)*3.1),0),IF(+((W24-3)*1.5+(X24-3)*3.1)>0,+((W24-3)*1.5+(X24-3)*3.1),0))<30,30,IF(D24="UNTUCA",IF(+((W24-3)*1.5+(X24-3)*3.1)>0,+((W24-3)*1.5+(X24-3)*3.1),0),IF(+((W24-3)*1.5+(X24-3)*3.1)>0,+((W24-3)*1.5+(X24-3)*3.1),0))) -> 30 | AA24: =+Y24+Z24 -> 50 | AB24: 0 | AC24: =+(S24-T24)*V24-'data 1'!$F$4 -> 24.7185 | AD24: =+(Q24-P24)*(R24-U24)*L24*V24/100 -> -4.3460761 | AE24: =+(Y24*V24-70)+V24*(Z24-IF(D24="UNTUCA",IF(+((W24-3)*2.5+(X24-3)*3.1)>0,+((W24-3)*1.5+(X24-3)*3.1),0),IF(+((W24-3)*1.5+(X24-3)*3.1)>0,+((W24-3)*1.5+(X24-3)*3.1),0))) -> -14.885 | AF24: =(L24-O24)*(R24-U24)*Q24*V24/100 -> 24.089993 | AG24: =+IF(D24="RONALD WILLIAN GARIBAY ESCUDERO",AC24+AD24+AE24+AF24+70,AC24+AD24+AE24+AF24)+70-53 -> 46.577417 | AH24: =31.1035*L24*Q24*1.1023*K24/100 -> 22.46434 | AI24: =+((+$AI$2-R24+U24)*L24*Q24*V24)/100 -> 23.058104 | AJ24: =31.1035*1.1023*K24*P24*O24/100 -> 19.829001 | AL24: =+IF(AB24*K24>0,AB24*K24,0) -> 0
A25: IP-1018 | B25: 45663 | C25: 45657 | D25: METAL EXTRACTION COMPANY S.A.C. | E25: {=XLOOKUP(D25,RUC!$B$3:$B$79,RUC!$D$3:$D$79)} -> 20606527439 | G25: 32 | H25: MINERAL | I25: 2.52 | J25: 1.2 | K25: =+I25-(I25*(J25/100)) -> 2.48976 | L25: 0.145 | M25: 0.135 | N25: 0.166 | O25: 0.15 | P25: 90 | Q25: 89.7 | R25: 2609.1 | S25: =IF((90+ROUNDDOWN(O25,1)*100)<95,95,(90+ROUNDDOWN(O25,1)*100)) -> 100 | U25: 90 | V25: 1.1023 | Y25: 20 | Z25: =IF(IF(D25="UNTUCA",IF(+((W25-3)*1.5+(X25-3)*3.1)>0,+((W25-3)*1.5+(X25-3)*3.1),0),IF(+((W25-3)*1.5+(X25-3)*3.1)>0,+((W25-3)*1.5+(X25-3)*3.1),0))<30,30,IF(D25="UNTUCA",IF(+((W25-3)*1.5+(X25-3)*3.1)>0,+((W25-3)*1.5+(X25-3)*3.1),0),IF(+((W25-3)*1.5+(X25-3)*3.1)>0,+((W25-3)*1.5+(X25-3)*3.1),0))) -> 30 | AA25: =+Y25+Z25 -> 50 | AB25: =+((O25*P25*(R25-U25)/100)-S25-AA25+T25)*V25 -> 209.52353 | AC25: =+(S25-T25)*V25-'data 1'!$F$4 -> 30.23 | AD25: =+(Q25-P25)*(R25-U25)*L25*V25/100 -> -1.2079097 | AE25: =+(Y25*V25-70)+V25*(Z25-IF(D25="UNTUCA",IF(+((W25-3)*2.5+(X25-3)*3.1)>0,+((W25-3)*1.5+(X25-3)*3.1),0),IF(+((W25-3)*1.5+(X25-3)*3.1)>0,+((W25-3)*1.5+(X25-3)*3.1),0))) -> -14.885 | AF25: =(L25-O25)*(R25-U25)*Q25*V25/100 -> -12.453966 | AG25: =+IF(D25="RONALD WILLIAN GARIBAY ESCUDERO",AC25+AD25+AE25+AF25+70,AC25+AD25+AE25+AF25)+70-53 -> 18.683125 | AH25: =31.1035*L25*Q25*1.1023*K25/100 -> 11.102659 | AI25: =+((+$AI$2-R25+U25)*L25*Q25*V25)/100 -> 43.140228 | AJ25: =31.1035*1.1023*K25*P25*O25/100 -> 11.523922 | AL25: =+IF(AB25*K25>0,AB25*K25,0) -> 521.66331
A26: IP-1020 | B26: 45660 | C26: 45657 | D26: MELCHOR AGUSTIN VERA PACHECO | E26: {=XLOOKUP(D26,RUC!$B$3:$B$79,RUC!$D$3:$D$79)} -> 10082235774 | G26: 68 | H26: MINERAL | I26: 7.1 | J26: 1.5 | K26: =+I26-(I26*(J26/100)) -> 6.9935 | L26: 0.662 | M26: 0.652 | N26: 0.652 | O26: =+ROUND((M26+N26)/2,3) -> 0.652 | P26: 90 | Q26: 89.72 | R26: 2609.1 | S26: 125 | U26: 80 | V26: 1.1023 | Z26: 10 | AA26: =+Y26+Z26 -> 10 | AB26: =+((O26*P26*(R26-U26)/100)-S26-AA26+T26)*V26 -> 1487.0863 | AC26: =+(S26-T26)*V26-'data 1'!$F$4 -> 57.7875 | AD26: =+(Q26-P26)*(R26-U26)*L26*V26/100 -> -5.167516 | AE26: =+(Y26*V26-70)+V26*(Z26-IF(D26="UNTUCA",IF(+((W26-3)*2.5+(X26-3)*3.1)>0,+((W26-3)*1.5+(X26-3)*3.1),0),IF(+((W26-3)*1.5+(X26-3)*3.1)>0,+((W26-3)*1.5+(X26-3)*3.1),0))) -> -58.977 | AF26: =(L26-O26)*(R26-U26)*Q26*V26/100 -> 25.012383 | AG26: =+IF(D26="RONALD WILLIAN GARIBAY ESCUDERO",AC26+AD26+AE26+AF26+70,AC26+AD26+AE26+AF26)+70 -> 88.655367 | AH26: =31.1035*L26*Q26*1.1023*K26/100 -> 142.41342 | AI26: =+((+$AI$2-R26+U26)*L26*Q26*V26)/100 -> 190.4543 | AJ26: =31.1035*1.1023*K26*P26*O26/100 -> 140.69989 | AL26: =+IF(AB26*K26>0,AB26*K26,0) -> 10399.938
A27: IP-1025 | B27: 45683 | C27: 45657 | D27: RONALD WILLIAN GARIBAY ESCUDERO | E27: {=XLOOKUP(D27,RUC!$B$3:$B$79,RUC!$D$3:$D$79)} -> #N/A | H27: MINERAL | I27: 7.53 | J27: 1.6 | K27: =+I27-(I27*(J27/100)) -> 7.40952 | L27: 0.062 | M27: 0.05208 | N27: 0.213 | O27: =+ROUND((M27+N27)/2,3) -> 0.133 | P27: 88 | Q27: 88.29 | R27: 2609.1 | S27: =IF((90+ROUNDDOWN(O27,1)*100)<95,95,(90+ROUNDDOWN(O27,1)*100)) -> 100 | U27: 100 | V27: 1.1023 | Z27: =IF(IF(D27="UNTUCA",IF(+((W27-3)*1.5+(X27-3)*3.1)>0,+((W27-3)*1.5+(X27-3)*3.1),0),IF(+((W27-3)*1.5+(X27-3)*3.1)>0,+((W27-3)*1.5+(X27-3)*3.1),0))<30,30,IF(D27="UNTUCA",IF(+((W27-3)*1.5+(X27-3)*3.1)>0,+((W27-3)*1.5+(X27-3)*3.1),0),IF(+((W27-3)*1.5+(X27-3)*3.1)>0,+((W27-3)*1.5+(X27-3)*3.1),0))) -> 30 | AA27: =+Y27+Z27 -> 30 | AB27: =+((O27*P27*(R27-U27)/100)-S27-AA27+T27)*V27 -> 180.408 | AC27: =+(S27-T27)*V27-'data 1'!$F$4 -> 30.23 | AD27: =+(Q27-P27)*(R27-U27)*L27*V27/100 -> 0.49728741 | AE27: =+(Y27*V27-70)+V27*(Z27-IF(D27="UNTUCA",IF(+((W27-3)*2.5+(X27-3)*3.1)>0,+((W27-3)*1.5+(X27-3)*3.1),0),IF(+((W27-3)*1.5+(X27-3)*3.1)>0,+((W27-3)*1.5+(X27-3)*3.1),0))) -> -36.931 | AF27: =(L27-O27)*(R27-U27)*Q27*V27/100 -> -173.37547 | AG27: =+IF(D27="RONALD WILLIAN GARIBAY ESCUDERO",AC27+AD27+AE27+AF27+70,AC27+AD27+AE27+AF27)+70-53 -> -92.579179 | AH27: =31.1035*L27*Q27*1.1023*K27/100 -> 13.906004 | AI27: =+((+$AI$2-R27+U27)*L27*Q27*V27)/100 -> 18.759607 | AJ27: =31.1035*1.1023*K27*P27*O27/100 -> 29.732639 | AL27: =+IF(AB27*K27>0,AB27*K27,0) -> 1336.7367
A28: IP-1026 | B28: 45683 | C28: 45657 | D28: RONALD WILLIAN GARIBAY ESCUDERO | E28: {=XLOOKUP(D28,RUC!$B$3:$B$79,RUC!$D$3:$D$79)} -> #N/A | H28: MINERAL | I28: 14.73 | J28: 1.7 | K28: =+I28-(I28*(J28/100)) -> 14.47959 | L28: 0.0965 | M28: 0.08685 | N28: 0.133 | O28: =+ROUND((M28+N28)/2,3) -> 0.11 | P28: 88 | Q28: 89.12 | R28: 2609.1 | S28: =IF((90+ROUNDDOWN(O28,1)*100)<95,95,(90+ROUNDDOWN(O28,1)*100)) -> 100 | U28: 100 | V28: 1.1023 | Z28: =IF(IF(D28="UNTUCA",IF(+((W28-3)*1.5+(X28-3)*3.1)>0,+((W28-3)*1.5+(X28-3)*3.1),0),IF(+((W28-3)*1.5+(X28-3)*3.1)>0,+((W28-3)*1.5+(X28-3)*3.1),0))<30,30,IF(D28="UNTUCA",IF(+((W28-3)*1.5+(X28-3)*3.1)>0,+((W28-3)*1.5+(X28-3)*3.1),0),IF(+((W28-3)*1.5+(X28-3)*3.1)>0,+((W28-3)*1.5+(X28-3)*3.1),0))) -> 30 | AA28: =+Y28+Z28 -> 30 | AB28: =+((O28*P28*(R28-U28)/100)-S28-AA28+T28)*V28 -> 124.42859 | AC28: =+(S28-T28)*V28-'data 1'!$F$4 -> 30.23 | AD28: =+(Q28-P28)*(R28-U28)*L28*V28/100 -> 2.989256 | AE28: =+(Y28*V28-70)+V28*(Z28-IF(D28="UNTUCA",IF(+((W28-3)*2.5+(X28-3)*3.1)>0,+((W28-3)*1.5+(X28-3)*3.1),0),IF(+((W28-3)*1.5+(X28-3)*3.1)>0,+((W28-3)*1.5+(X28-3)*3.1),0))) -> -36.931 | AF28: =(L28-O28)*(R28-U28)*Q28*V28/100 -> -33.275664 | AG28: =+IF(D28="RONALD WILLIAN GARIBAY ESCUDERO",AC28+AD28+AE28+AF28+70,AC28+AD28+AE28+AF28)+70-53 -> 50.012592 | AH28: =31.1035*L28*Q28*1.1023*K28/100 -> 42.694096 | AI28: =+((+$AI$2-R28+U28)*L28*Q28*V28)/100 -> 29.47291 | AJ28: =31.1035*1.1023*K28*P28*O28/100 -> 48.055233 | AL28: =+IF(AB28*K28>0,AB28*K28,0) -> 1801.675
A29: IP-1029 | B29: 45674 | C29: 45660 | D29: SOTOMAYOR CORAZAO WISTHERMUNDO | E29: {=XLOOKUP(D29,RUC!$B$3:$B$79,RUC!$D$3:$D$79)} -> 10416085884 | G29: AGRANEL | H29: MINERAL | I29: 30.58 | J29: 5.05 | K29: =+I29-(I29*(J29/100)) -> 29.03571 | L29: 0.168 | M29: 0.158 | N29: 0.158 | O29: =+ROUND((M29+N29)/2,3) -> 0.158 | P29: 90 | Q29: 89.75 | R29: 2616.45 | S29: 85 | U29: 90 | V29: 1.1023 | Z29: 15 | AA29: 15 | AB29: =+((O29*P29*(R29-U29)/100)-S29-AA29+T29)*V29 -> 285.78361 | AC29: =+(S29-T29)*V29-'data 1'!$F$4 -> 13.6955 | AD29: =+(Q29-P29)*(R29-U29)*L29*V29/100 -> -1.1696605 | AE29: =+(Y29*V29-70)+V29*(Z29-IF(D29="UNTUCA",IF(+((W29-3)*2.5+(X29-3)*3.1)>0,+((W29-3)*1.5+(X29-3)*3.1),0),IF(+((W29-3)*1.5+(X29-3)*3.1)>0,+((W29-3)*1.5+(X29-3)*3.1),0))) -> -53.4655 | AF29: =(L29-O29)*(R29-U29)*Q29*V29/100 -> 24.99453 | AG29: =+IF(D29="RONALD WILLIAN GARIBAY ESCUDERO",AC29+AD29+AE29+AF29+70,AC29+AD29+AE29+AF29)+70-10 -> 44.054869 | AH29: =31.1035*L29*Q29*1.1023*K29/100 -> 150.10158 | AI29: =+((+$AI$2-R29+U29)*L29*Q29*V29)/100 -> 48.789417 | AJ29: =31.1035*1.1023*K29*P29*O29/100 -> 141.56018 | AL29: =+IF(AB29*K29>0,AB29*K29,0) -> 8297.93
A30: IP-1030 | B30: 45674 | C30: 45660 | D30: SOTOMAYOR CORAZAO MORAYMA | E30: {=XLOOKUP(D30,RUC!$B$3:$B$79,RUC!$D$3:$D$79)} -> 10421580605 | G30: AGRANEL | H30: MINERAL | I30: 29.75 | J30: 10.2 | K30: =+I30-(I30*(J30/100)) -> 26.7155 | L30: 0.164 | M30: 0.154 | N30: 0.154 | O30: =+ROUND((M30+N30)/2,3) -> 0.154 | P30: 90 | Q30: 89.84 | R30: 2616.45 | S30: 85 | U30: 90 | V30: 1.1023 | Y30: 30 | Z30: 15 | AA30: 15 | AB30: =+((O30*P30*(R30-U30)/100)-S30-AA30+T30)*V30 -> 275.75795 | AC30: =+(S30-T30)*V30-'data 1'!$F$4 -> 13.6955 | AD30: =+(Q30-P30)*(R30-U30)*L30*V30/100 -> -0.73075929 | AE30: =+(Y30*V30-70)+V30*(Z30-IF(D30="UNTUCA",IF(+((W30-3)*2.5+(X30-3)*3.1)>0,+((W30-3)*1.5+(X30-3)*3.1),0),IF(+((W30-3)*1.5+(X30-3)*3.1)>0,+((W30-3)*1.5+(X30-3)*3.1),0))) -> -20.3965 | AF30: =(L30-O30)*(R30-U30)*Q30*V30/100 -> 25.019594 | AG30: =+IF(D30="RONALD WILLIAN GARIBAY ESCUDERO",AC30+AD30+AE30+AF30+70,AC30+AD30+AE30+AF30)+70-10 -> 77.587835 | AH30: =31.1035*L30*Q30*1.1023*K30/100 -> 134.95406 | AI30: =+((+$AI$2-R30+U30)*L30*Q30*V30)/100 -> 47.675525 | AJ30: =31.1035*1.1023*K30*P30*O30/100 -> 126.95085 | AL30: =+IF(AB30*K30>0,AB30*K30,0) -> 7367.0115
A31: IP-1032 | B31: 45667 | C31: 45661 | D31: EMPRESA MINERA MARKATA CAS S.A.C. | E31: {=XLOOKUP(D31,RUC!$B$3:$B$79,RUC!$D$3:$D$79)} -> 20606526599 | G31: 180 | H31: MINERAL | I31: 14.74 | J31: 1.5 | K31: =+I31-(I31*(J31/100)) -> 14.5189 | L31: 0.368 | M31: 0.353 | N31: 0.353 | O31: =+ROUND((M31+N31)/2,3) -> 0.353 | P31: 90 | Q31: 89.86 | R31: 2646.8 | S31: =IF((90+ROUNDDOWN(O31,1)*100)<95,95,(90+ROUNDDOWN(O31,1)*100)) -> 120 | U31: 120 | V31: 1.1023 | Y31: 20 | Z31: =IF(IF(D31="UNTUCA",IF(+((W31-3)*1.5+(X31-3)*3.1)>0,+((W31-3)*1.5+(X31-3)*3.1),0),IF(+((W31-3)*1.5+(X31-3)*3.1)>0,+((W31-3)*1.5+(X31-3)*3.1),0))<30,30,IF(D31="UNTUCA",IF(+((W31-3)*1.5+(X31-3)*3.1)>0,+((W31-3)*1.5+(X31-3)*3.1),0),IF(+((W31-3)*1.5+(X31-3)*3.1)>0,+((W31-3)*1.5+(X31-3)*3.1),0))) -> 30 | AA31: =+Y31+Z31 -> 50 | AB31: =+((O31*P31*(R31-U31)/100)-S31-AA31+T31)*V31 -> 697.49615 | AC31: =+(S31-T31)*V31-'data 1'!$F$4 -> 52.276 | AD31: =+(Q31-P31)*(R31-U31)*L31*V31/100 -> -1.4349823 | AE31: =+(Y31*V31-70)+V31*(Z31-IF(D31="UNTUCA",IF(+((W31-3)*2.5+(X31-3)*3.1)>0,+((W31-3)*1.5+(X31-3)*3.1),0),IF(+((W31-3)*1.5+(X31-3)*3.1)>0,+((W31-3)*1.5+(X31-3)*3.1),0))) -> -14.885 | AF31: =(L31-O31)*(R31-U31)*Q31*V31/100 -> 37.542946 | AG31: =+IF(D31="RONALD WILLIAN GARIBAY ESCUDERO",AC31+AD31+AE31+AF31+70,AC31+AD31+AE31+AF31)+70-53 -> 90.498964 | AH31: =31.1035*L31*Q31*1.1023*K31/100 -> 164.6103 | AI31: =+((+$AI$2-R31+U31)*L31*Q31*V31)/100 -> 106.87546 | AJ31: =31.1035*1.1023*K31*P31*O31/100 -> 158.14665 | AL31: =+IF(AB31*K31>0,AB31*K31,0) -> 10126.877
A32: IP-1033 | B32: 45673 | C32: 45666 | D32: EXPLORACIONES CLAUDIA Y KAREN E.I.R.L. | E32: {=XLOOKUP(D32,RUC!$B$3:$B$79,RUC!$D$3:$D$79)} -> 20601620147 | G32: 51 | H32: M.LLAMPO | I32: 4.06 | J32: 1.1 | K32: =+I32-(I32*(J32/100)) -> 4.01534 | L32: 0.457 | M32: 0.438 | N32: 0.438 | O32: =+ROUND((M32+N32)/2,3) -> 0.438 | P32: 90 | Q32: 90.25 | R32: 2650.85 | S32: 100 | U32: 90 | V32: 1.1023 | Y32: 10 | Z32: =IF(IF(D32="UNTUCA",IF(+((W32-3)*1.5+(X32-3)*3.1)>0,+((W32-3)*1.5+(X32-3)*3.1),0),IF(+((W32-3)*1.5+(X32-3)*3.1)>0,+((W32-3)*1.5+(X32-3)*3.1),0))<30,30,IF(D32="UNTUCA",IF(+((W32-3)*1.5+(X32-3)*3.1)>0,+((W32-3)*1.5+(X32-3)*3.1),0),IF(+((W32-3)*1.5+(X32-3)*3.1)>0,+((W32-3)*1.5+(X32-3)*3.1),0))) -> 30 | AA32: =+Y32+Z32 -> 40 | AB32: =+((O32*P32*(R32-U32)/100)-S32-AA32+T32)*V32 -> 958.4356 | AC32: =+(S32-T32)*V32-'data 1'!$F$4 -> 30.23 | AD32: =+(Q32-P32)*(R32-U32)*L32*V32/100 -> 3.2250775 | AE32: =+(Y32*V32-70)+V32*(Z32-IF(D32="UNTUCA",IF(+((W32-3)*2.5+(X32-3)*3.1)>0,+((W32-3)*1.5+(X32-3)*3.1),0),IF(+((W32-3)*1.5+(X32-3)*3.1)>0,+((W32-3)*1.5+(X32-3)*3.1),0))) -> -25.908 | AF32: =(L32-O32)*(R32-U32)*Q32*V32/100 -> 48.404391 | AG32: =+IF(D32="RONALD WILLIAN GARIBAY ESCUDERO",AC32+AD32+AE32+AF32+70,AC32+AD32+AE32+AF32)+70-53 -> 72.951468 | AH32: =31.1035*L32*Q32*1.1023*K32/100 -> 56.779924 | AI32: =+((+$AI$2-R32+U32)*L32*Q32*V32)/100 -> 117.81876 | AJ32: =31.1035*1.1023*K32*P32*O32/100 -> 54.268525 | AL32: =+IF(AB32*K32>0,AB32*K32,0) -> 3848.4448
A33: IP-1034 | B33: 45673 | C33: 45666 | D33: EXPLORACIONES CLAUDIA Y KAREN E.I.R.L. | E33: {=XLOOKUP(D33,RUC!$B$3:$B$79,RUC!$D$3:$D$79)} -> 20601620147 | G33: 11 | H33: M.LLAMPO | I33: 0.78 | J33: 1.2 | K33: =+I33-(I33*(J33/100)) -> 0.77064 | L33: 0.574 | M33: 0.551 | N33: 0.61 | O33: =+ROUND((M33+N33)/2,3) -> 0.581 | P33: 90 | Q33: 90.4 | R33: 2650.85 | S33: 110 | U33: 90 | V33: 1.1023 | Y33: 10 | Z33: =IF(IF(D33="UNTUCA",IF(+((W33-3)*1.5+(X33-3)*3.1)>0,+((W33-3)*1.5+(X33-3)*3.1),0),IF(+((W33-3)*1.5+(X33-3)*3.1)>0,+((W33-3)*1.5+(X33-3)*3.1),0))<30,30,IF(D33="UNTUCA",IF(+((W33-3)*1.5+(X33-3)*3.1)>0,+((W33-3)*1.5+(X33-3)*3.1),0),IF(+((W33-3)*1.5+(X33-3)*3.1)>0,+((W33-3)*1.5+(X33-3)*3.1),0))) -> 30 | AA33: =+Y33+Z33 -> 40 | AB33: =+((O33*P33*(R33-U33)/100)-S33-AA33+T33)*V33 -> 1310.7102 | AC33: =+(S33-T33)*V33-'data 1'!$F$4 -> 41.253 | AD33: =+(Q33-P33)*(R33-U33)*L33*V33/100 -> 6.4812061 | AE33: =+(Y33*V33-70)+V33*(Z33-IF(D33="UNTUCA",IF(+((W33-3)*2.5+(X33-3)*3.1)>0,+((W33-3)*1.5+(X33-3)*3.1),0),IF(+((W33-3)*1.5+(X33-3)*3.1)>0,+((W33-3)*1.5+(X33-3)*3.1),0))) -> -25.908 | AF33: =(L33-O33)*(R33-U33)*Q33*V33/100 -> -17.862836 | AG33: =+IF(D33="RONALD WILLIAN GARIBAY ESCUDERO",AC33+AD33+AE33+AF33+70,AC33+AD33+AE33+AF33)+70-53 -> 20.96337 | AH33: =31.1035*L33*Q33*1.1023*K33/100 -> 13.71011 | AI33: =+((+$AI$2-R33+U33)*L33*Q33*V33)/100 -> 148.22837 | AJ33: =31.1035*1.1023*K33*P33*O33/100 -> 13.815902 | AL33: =+IF(AB33*K33>0,AB33*K33,0) -> 1010.0857
A34: IP-1035 | B34: 45673 | C34: 45666 | D34: EXPLORACIONES CLAUDIA Y KAREN E.I.R.L. | E34: {=XLOOKUP(D34,RUC!$B$3:$B$79,RUC!$D$3:$D$79)} -> 20601620147 | G34: AGRANEL | H34: MINERAL | I34: 8.45 | J34: 6.85 | K34: =+I34-(I34*(J34/100)) -> 7.871175 | L34: 0.105 | M34: 0.095 | N34: 0.116 | O34: =+ROUND((M34+N34)/2,3) -> 0.106 | P34: 85 | Q34: 90.12 | R34: 2650.85 | S34: 110 | U34: 90 | V34: 1.1023 | Z34: =IF(IF(D34="UNTUCA",IF(+((W34-3)*1.5+(X34-3)*3.1)>0,+((W34-3)*1.5+(X34-3)*3.1),0),IF(+((W34-3)*1.5+(X34-3)*3.1)>0,+((W34-3)*1.5+(X34-3)*3.1),0))<30,30,IF(D34="UNTUCA",IF(+((W34-3)*1.5+(X34-3)*3.1)>0,+((W34-3)*1.5+(X34-3)*3.1),0),IF(+((W34-3)*1.5+(X34-3)*3.1)>0,+((W34-3)*1.5+(X34-3)*3.1),0))) -> 30 | AA34: =+Y34+Z34 -> 30 | AB34: =+((O34*P34*(R34-U34)/100)-S34-AA34+T34)*V34 -> 100.01453 | AC34: =+(S34-T34)*V34-'data 1'!$F$4 -> 41.253 | AD34: =+(Q34-P34)*(R34-U34)*L34*V34/100 -> 15.175507 | AE34: =+(Y34*V34-70)+V34*(Z34-IF(D34="UNTUCA",IF(+((W34-3)*2.5+(X34-3)*3.1)>0,+((W34-3)*1.5+(X34-3)*3.1),0),IF(+((W34-3)*1.5+(X34-3)*3.1)>0,+((W34-3)*1.5+(X34-3)*3.1),0))) -> -36.931 | AF34: =(L34-O34)*(R34-U34)*Q34*V34/100 -> -2.5439298 | AG34: =+IF(D34="RONALD WILLIAN GARIBAY ESCUDERO",AC34+AD34+AE34+AF34+70,AC34+AD34+AE34+AF34)+70-53 -> 33.953577 | AH34: =31.1035*L34*Q34*1.1023*K34/100 -> 25.536367 | AI34: =+((+$AI$2-R34+U34)*L34*Q34*V34)/100 -> 27.030962 | AJ34: =31.1035*1.1023*K34*P34*O34/100 -> 24.314953 | AL34: =+IF(AB34*K34>0,AB34*K34,0) -> 787.23186
A35: IP-1036 | B35: 45673 | C35: 45666 | D35: EXPLORACIONES CLAUDIA Y KAREN E.I.R.L. | E35: {=XLOOKUP(D35,RUC!$B$3:$B$79,RUC!$D$3:$D$79)} -> 20601620147 | G35: 85 | H35: MINERAL | I35: 0.75 | J35: 10.1 | K35: =+I35-(I35*(J35/100)) -> 0.67425 | L35: 0.165 | M35: 0.141 | N35: 0.141 | O35: =+ROUND((M35+N35)/2,3) -> 0.141 | P35: 85 | Q35: 90.33 | R35: 2650.85 | S35: 110 | U35: 90 | V35: 1.1023 | Z35: =IF(IF(D35="UNTUCA",IF(+((W35-3)*1.5+(X35-3)*3.1)>0,+((W35-3)*1.5+(X35-3)*3.1),0),IF(+((W35-3)*1.5+(X35-3)*3.1)>0,+((W35-3)*1.5+(X35-3)*3.1),0))<30,30,IF(D35="UNTUCA",IF(+((W35-3)*1.5+(X35-3)*3.1)>0,+((W35-3)*1.5+(X35-3)*3.1),0),IF(+((W35-3)*1.5+(X35-3)*3.1)>0,+((W35-3)*1.5+(X35-3)*3.1),0))) -> 30 | AA35: =+Y35+Z35 -> 30 | AB35: =+((O35*P35*(R35-U35)/100)-S35-AA35+T35)*V35 -> 183.99357 | AC35: =+(S35-T35)*V35-'data 1'!$F$4 -> 41.253 | AD35: =+(Q35-P35)*(R35-U35)*L35*V35/100 -> 24.825334 | AE35: =+(Y35*V35-70)+V35*(Z35-IF(D35="UNTUCA",IF(+((W35-3)*2.5+(X35-3)*3.1)>0,+((W35-3)*1.5+(X35-3)*3.1),0),IF(+((W35-3)*1.5+(X35-3)*3.1)>0,+((W35-3)*1.5+(X35-3)*3.1),0))) -> -36.931 | AF35: =(L35-O35)*(R35-U35)*Q35*V35/100 -> 61.196587 | AG35: =+IF(D35="RONALD WILLIAN GARIBAY ESCUDERO",AC35+AD35+AE35+AF35+70,AC35+AD35+AE35+AF35)+70-53 -> 107.34392 | AH35: =31.1035*L35*Q35*1.1023*K35/100 -> 3.4454502 | AI35: =+((+$AI$2-R35+U35)*L35*Q35*V35)/100 -> 42.576208 | AJ35: =31.1035*1.1023*K35*P35*O35/100 -> 2.7705632 | AL35: =+IF(AB35*K35>0,AB35*K35,0) -> 124.05767
A36: IP-1037 | B36: 45671 | C36: 45666 | D36: EXPLORACIONES CLAUDIA Y KAREN E.I.R.L. | E36: {=XLOOKUP(D36,RUC!$B$3:$B$79,RUC!$D$3:$D$79)} -> 20601620147 | G36: AGRANEL | H36: MINERAL | I36: 10.65 | J36: 11.1 | K36: =+I36-(I36*(J36/100)) -> 9.46785 | L36: 0.161 | M36: 0.151 | N36: 0.162 | O36: =+ROUND((M36+N36)/2,3) -> 0.157 | P36: 90 | Q36: 91.22 | R36: 2650.85 | S36: =IF((90+ROUNDDOWN(O36,1)*100)<95,95,(90+ROUNDDOWN(O36,1)*100)) -> 100 | U36: 90 | V36: 1.1023 | Z36: =IF(IF(D36="UNTUCA",IF(+((W36-3)*1.5+(X36-3)*3.1)>0,+((W36-3)*1.5+(X36-3)*3.1),0),IF(+((W36-3)*1.5+(X36-3)*3.1)>0,+((W36-3)*1.5+(X36-3)*3.1),0))<30,30,IF(D36="UNTUCA",IF(+((W36-3)*1.5+(X36-3)*3.1)>0,+((W36-3)*1.5+(X36-3)*3.1),0),IF(+((W36-3)*1.5+(X36-3)*3.1)>0,+((W36-3)*1.5+(X36-3)*3.1),0))) -> 30 | AA36: =+Y36+Z36 -> 30 | AB36: =+((O36*P36*(R36-U36)/100)-S36-AA36+T36)*V36 -> 255.56617 | AC36: =+(S36-T36)*V36-'data 1'!$F$4 -> 30.23 | AD36: =+(Q36-P36)*(R36-U36)*L36*V36/100 -> 5.5445928 | AE36: =+(Y36*V36-70)+V36*(Z36-IF(D36="UNTUCA",IF(+((W36-3)*2.5+(X36-3)*3.1)>0,+((W36-3)*1.5+(X36-3)*3.1),0),IF(+((W36-3)*1.5+(X36-3)*3.1)>0,+((W36-3)*1.5+(X36-3)*3.1),0))) -> -36.931 | AF36: =(L36-O36)*(R36-U36)*Q36*V36/100 -> 10.299924 | AG36: =+IF(D36="RONALD WILLIAN GARIBAY ESCUDERO",AC36+AD36+AE36+AF36+70,AC36+AD36+AE36+AF36)+70-53 -> 26.143516 | AH36: =31.1035*L36*Q36*1.1023*K36/100 -> 47.673428 | AI36: =+((+$AI$2-R36+U36)*L36*Q36*V36)/100 -> 41.953381 | AJ36: =31.1035*1.1023*K36*P36*O36/100 -> 45.867239 | AL36: =+IF(AB36*K36>0,AB36*K36,0) -> 2419.6621
A37: IP-1038 | B37: 45672 | C37: 45666 | D37: MINERA AURIFERA 2 DE DICIEMBRE CALPA RENACE S.A. | E37: {=XLOOKUP(D37,RUC!$B$3:$B$79,RUC!$D$3:$D$79)} -> #N/A | G37: 50 | H37: MINERAL | I37: 6.27 | J37: 1 | K37: =+I37-(I37*(J37/100)) -> 6.2073 | L37: 0.523 | M37: 0.502 | N37: 0.547 | O37: =+ROUND((M37+N37)/2,3) -> 0.525 | P37: 90 | Q37: 90.23 | R37: 2674.6 | S37: =IF((90+ROUNDDOWN(O37,1)*100)<95,95,(90+ROUNDDOWN(O37,1)*100))-5 -> 135 | U37: 90 | V37: 1.1023 | Z37: 25 | AA37: =+Y37+Z37 -> 25 | AB37: =+((O37*P37*(R37-U37)/100)-S37-AA37+T37)*V37 -> 1169.7867 | AC37: =+(S37-T37)*V37-'data 1'!$F$4 -> 68.8105 | AD37: =+(Q37-P37)*(R37-U37)*L37*V37/100 -> 3.4270676 | AE37: =+(Y37*V37-70)+V37*(Z37-IF(D37="UNTUCA",IF(+((W37-3)*2.5+(X37-3)*3.1)>0,+((W37-3)*1.5+(X37-3)*3.1),0),IF(+((W37-3)*1.5+(X37-3)*3.1)>0,+((W37-3)*1.5+(X37-3)*3.1),0))) -> -42.4425 | AF37: =(L37-O37)*(R37-U37)*Q37*V37/100 -> -5.1413137 | AG37: =+IF(D37="RONALD WILLIAN GARIBAY ESCUDERO",AC37+AD37+AE37+AF37+70,AC37+AD37+AE37+AF37)+70-30-5-3 -> 56.653754 | AH37: =31.1035*L37*Q37*1.1023*K37/100 -> 100.43023 | AI37: =+((+$AI$2-R37+U37)*L37*Q37*V37)/100 -> 122.45003 | AJ37: =31.1035*1.1023*K37*P37*O37/100 -> 100.5573 | AL37: =+IF(AB37*K37>0,AB37*K37,0) -> 7261.2168
A38: IP-1039 | B38: 45672 | C38: 45666 | D38: MINERA AURIFERA 2 DE DICIEMBRE CALPA RENACE S.A. | E38: {=XLOOKUP(D38,RUC!$B$3:$B$79,RUC!$D$3:$D$79)} -> #N/A | G38: 50 | H38: MINERAL | I38: 6.54 | J38: 0.95 | K38: =+I38-(I38*(J38/100)) -> 6.47787 | L38: 0.703 | M38: 0.674 | N38: 0.747 | O38: =+ROUND((M38+N38)/2,3) -> 0.711 | P38: 90 | Q38: 90.15 | R38: 2674.6 | S38: =IF((90+ROUNDDOWN(O38,1)*100)<95,95,(90+ROUNDDOWN(O38,1)*100))-5 -> 155 | U38: 90 | V38: 1.1023 | Z38: 25 | AA38: =+Y38+Z38 -> 25 | AB38: =+((O38*P38*(R38-U38)/100)-S38-AA38+T38)*V38 -> 1624.664 | AC38: =+(S38-T38)*V38-'data 1'!$F$4 -> 90.8565 | AD38: =+(Q38-P38)*(R38-U38)*L38*V38/100 -> 3.0042753 | AE38: =+(Y38*V38-70)+V38*(Z38-IF(D38="UNTUCA",IF(+((W38-3)*2.5+(X38-3)*3.1)>0,+((W38-3)*1.5+(X38-3)*3.1),0),IF(+((W38-3)*1.5+(X38-3)*3.1)>0,+((W38-3)*1.5+(X38-3)*3.1),0))) -> -42.4425 | AF38: =(L38-O38)*(R38-U38)*Q38*V38/100 -> -20.547021 | AG38: =+IF(D38="RONALD WILLIAN GARIBAY ESCUDERO",AC38+AD38+AE38+AF38+70,AC38+AD38+AE38+AF38)+70-30-5-3 -> 62.871254 | AH38: =31.1035*L38*Q38*1.1023*K38/100 -> 140.75452 | AI38: =+((+$AI$2-R38+U38)*L38*Q38*V38)/100 -> 164.44752 | AJ38: =31.1035*1.1023*K38*P38*O38/100 -> 142.11941 | AL38: =+IF(AB38*K38>0,AB38*K38,0) -> 10524.362
A39: IP-1040 | B39: 45672 | C39: 45666 | D39: MINERA AURIFERA 2 DE DICIEMBRE CALPA RENACE S.A. | E39: {=XLOOKUP(D39,RUC!$B$3:$B$79,RUC!$D$3:$D$79)} -> #N/A | G39: 50 | H39: MINERAL | I39: 6.92 | J39: 1 | K39: =+I39-(I39*(J39/100)) -> 6.8508 | L39: 0.712 | M39: 0.684 | N39: 0.684 | O39: =+ROUND((M39+N39)/2,3) -> 0.684 | P39: 90 | Q39: 90.09 | R39: 2674.6 | S39: =IF((90+ROUNDDOWN(O39,1)*100)<95,95,(90+ROUNDDOWN(O39,1)*100))-5 -> 145 | U39: 90 | V39: 1.1023 | Z39: 25 | AA39: =+Y39+Z39 -> 25 | AB39: =+((O39*P39*(R39-U39)/100)-S39-AA39+T39)*V39 -> 1566.4562 | AC39: =+(S39-T39)*V39-'data 1'!$F$4 -> 79.8335 | AD39: =+(Q39-P39)*(R39-U39)*L39*V39/100 -> 1.8256421 | AE39: =+(Y39*V39-70)+V39*(Z39-IF(D39="UNTUCA",IF(+((W39-3)*2.5+(X39-3)*3.1)>0,+((W39-3)*1.5+(X39-3)*3.1),0),IF(+((W39-3)*1.5+(X39-3)*3.1)>0,+((W39-3)*1.5+(X39-3)*3.1),0))) -> -42.4425 | AF39: =(L39-O39)*(R39-U39)*Q39*V39/100 -> 71.86671 | AG39: =+IF(D39="RONALD WILLIAN GARIBAY ESCUDERO",AC39+AD39+AE39+AF39+70,AC39+AD39+AE39+AF39)+70-30-5-3 -> 143.08335 | AH39: =31.1035*L39*Q39*1.1023*K39/100 -> 150.66311 | AI39: =+((+$AI$2-R39+U39)*L39*Q39*V39)/100 -> 166.44197 | AJ39: =31.1035*1.1023*K39*P39*O39/100 -> 144.59357 | AL39: =+IF(AB39*K39>0,AB39*K39,0) -> 10731.478
A40: IP-1041 | B40: 45672 | C40: 45666 | D40: MINERA AURIFERA 2 DE DICIEMBRE CALPA RENACE S.A. | E40: {=XLOOKUP(D40,RUC!$B$3:$B$79,RUC!$D$3:$D$79)} -> #N/A | G40: 50 | H40: MINERAL | I40: 6.49 | J40: 0.91 | K40: =+I40-(I40*(J40/100)) -> 6.430941 | L40: 0.738 | M40: 0.708 | N40: 0.708 | O40: =+ROUND((M40+N40)/2,3) -> 0.708 | P40: 90 | Q40: 90.28 | R40: 2674.6 | S40: =IF((90+ROUNDDOWN(O40,1)*100)<95,95,(90+ROUNDDOWN(O40,1)*100))-5 -> 155 | U40: 90 | V40: 1.1023 | Z40: 25 | AA40: =+Y40+Z40 -> 25 | AB40: =+((O40*P40*(R40-U40)/100)-S40-AA40+T40)*V40 -> 1616.9717 | AC40: =+(S40-T40)*V40-'data 1'!$F$4 -> 90.8565 | AD40: =+(Q40-P40)*(R40-U40)*L40*V40/100 -> 5.8871831 | AE40: =+(Y40*V40-70)+V40*(Z40-IF(D40="UNTUCA",IF(+((W40-3)*2.5+(X40-3)*3.1)>0,+((W40-3)*1.5+(X40-3)*3.1),0),IF(+((W40-3)*1.5+(X40-3)*3.1)>0,+((W40-3)*1.5+(X40-3)*3.1),0))) -> -42.4425 | AF40: =(L40-O40)*(R40-U40)*Q40*V40/100 -> 77.16244 | AG40: =+IF(D40="RONALD WILLIAN GARIBAY ESCUDERO",AC40+AD40+AE40+AF40+70,AC40+AD40+AE40+AF40)+70-30-5-3 -> 163.46362 | AH40: =31.1035*L40*Q40*1.1023*K40/100 -> 146.90328 | AI40: =+((+$AI$2-R40+U40)*L40*Q40*V40)/100 -> 172.88375 | AJ40: =31.1035*1.1023*K40*P40*O40/100 -> 140.49451 | AL40: =+IF(AB40*K40>0,AB40*K40,0) -> 10398.65
A41: IP-1042 | B41: 45672 | C41: 45666 | D41: MINERA AURIFERA 2 DE DICIEMBRE CALPA RENACE S.A. | E41: {=XLOOKUP(D41,RUC!$B$3:$B$79,RUC!$D$3:$D$79)} -> #N/A | G41: 50 | H41: MINERAL | I41: 6.97 | J41: 0.87 | K41: =+I41-(I41*(J41/100)) -> 6.909361 | L41: 0.725 | M41: 0.696 | N41: 0.771 | O41: =+ROUND((M41+N41)/2,3) -> 0.734 | P41: 90 | Q41: 90.17 | R41: 2674.6 | S41: =IF((90+ROUNDDOWN(O41,1)*100)<95,95,(90+ROUNDDOWN(O41,1)*100))-5 -> 155 | U41: 90 | V41: 1.1023 | Z41: 25 | AA41: =+Y41+Z41 -> 25 | AB41: =+((O41*P41*(R41-U41)/100)-S41-AA41+T41)*V41 -> 1683.6384 | AC41: =+(S41-T41)*V41-'data 1'!$F$4 -> 90.8565 | AD41: =+(Q41-P41)*(R41-U41)*L41*V41/100 -> 3.5113981 | AE41: =+(Y41*V41-70)+V41*(Z41-IF(D41="UNTUCA",IF(+((W41-3)*2.5+(X41-3)*3.1)>0,+((W41-3)*1.5+(X41-3)*3.1),0),IF(+((W41-3)*1.5+(X41-3)*3.1)>0,+((W41-3)*1.5+(X41-3)*3.1),0))) -> -42.4425 | AF41: =(L41-O41)*(R41-U41)*Q41*V41/100 -> -23.120527 | AG41: =+IF(D41="RONALD WILLIAN GARIBAY ESCUDERO",AC41+AD41+AE41+AF41+70,AC41+AD41+AE41+AF41)+70-30-5-3 -> 60.804871 | AH41: =31.1035*L41*Q41*1.1023*K41/100 -> 154.86277 | AI41: =+((+$AI$2-R41+U41)*L41*Q41*V41)/100 -> 169.63144 | AJ41: =31.1035*1.1023*K41*P41*O41/100 -> 156.48962 | AL41: =+IF(AB41*K41>0,AB41*K41,0) -> 11632.866
...

Sheet 18
AG1: Profit Terminos | AH1: Au Real (con Rec) | AI1: Profit RC | AJ1: Au Comprado | AL1: Valor
I2: =SUBTOTAL(9,I4:I9246) -> 629.56 | K2: =SUBTOTAL(9,K4:K9246) -> 604.60735 | L2: =SUMPRODUCT(L5:L90,K5:K90)/K2 -> 0.36407714 | Q2: =+SUMPRODUCT(Q5:Q62,AH5:AH62)/SUM(AH5:AH62) -> 90.047409 | R2: =+SUMPRODUCT(R5:R62,AH5:AH62)/SUM(AH5:AH62) -> 2746.4108 | AG2: =SUMPRODUCT($AG5:$AG886,$K5:$K886)/SUM($K5:$K886) -> 66.038922 | AI2: 2900
A3: Lote | B3: F emision | C3: F recepcion | D3: Nombre | E3: RUC | F3: Minero | G3: Sacos | I3: TMH | J3: %H2O | K3: TMS | L3: Oz/tc Planta | M3: Oz/tc comercial | N3: Oz/tc Minero | O3: Oz/tc Pomedio | P3: % Rec Liq | Q3: % Rec Planta | R3: Inter US$ | S3: TC US$ x tc | T3: Bono | U3: Riesgo | V3: Factor | W3: Soda | X3: Cianuro | Y3: Gasto acopio x tm | Z3: Insumos planta x tm | AA3: Insumos liq x tm | AB3: Precio x TMS | AC3: profit maquila | AD3: Profit Rec | AE3: Profit Consumo | AF3: Profit Leyes | AG3: Profit Total $/TM | AH3: =SUBTOTAL(9,AH5:AH9247) -> 6791.7303 | AI3: =SUMPRODUCT(K5:K62,AI5:AI62)/K2 -> 61.117475 | AJ3: =SUBTOTAL(9,AJ5:AJ9247) -> 6638.7725 | AL3: =SUBTOTAL(9,AL5:AL9247) -> 476936.16 | AM3: 6138
AM4: 7010
A5: IP-1031 | C5: 45660 | D5: LLASA YUCRA YOLANDA | E5: {=XLOOKUP(D5,RUC!$B$3:$B$79,RUC!$D$3:$D$79)} -> #N/A | G5: 60 | H5: MINERAL | I5: 4.78 | J5: 1.4 | K5: =+I5-(I5*(J5/100)) -> 4.71308 | L5: 0.07 | M5: 0.067 | N5: 0.067 | O5: =+ROUND((M5+N5)/2,3) -> 0.067 | P5: 80 | Q5: 87.92 | R5: 2646.8 | S5: =IF((90+ROUNDDOWN(O5,1)*100)<95,95,(90+ROUNDDOWN(O5,1)*100)) -> 95 | U5: 120 | V5: 1.1023 | Y5: 30 | Z5: =IF(IF(D5="UNTUCA",IF(+((W5-3)*1.5+(X5-3)*3.1)>0,+((W5-3)*1.5+(X5-3)*3.1),0),IF(+((W5-3)*1.5+(X5-3)*3.1)>0,+((W5-3)*1.5+(X5-3)*3.1),0))<30,30,IF(D5="UNTUCA",IF(+((W5-3)*1.5+(X5-3)*3.1)>0,+((W5-3)*1.5+(X5-3)*3.1),0),IF(+((W5-3)*1.5+(X5-3)*3.1)>0,+((W5-3)*1.5+(X5-3)*3.1),0))) -> 30 | AA5: =+Y5+Z5 -> 60 | AB5: =+((O5*P5*(R5-U5)/100)-S5-AA5+T5)*V5 -> -21.564868 | AC5: =+(S5-T5)*V5-'data 1'!$F$4 -> 24.7185 | AD5: =+(Q5-P5)*(R5-U5)*L5*V5/100 -> 15.441657 | AE5: =+(Y5*V5-70)+V5*(Z5-IF(D5="UNTUCA",IF(+((W5-3)*2.5+(X5-3)*3.1)>0,+((W5-3)*1.5+(X5-3)*3.1),0),IF(+((W5-3)*1.5+(X5-3)*3.1)>0,+((W5-3)*1.5+(X5-3)*3.1),0))) -> -3.862 | AF5: =(L5-O5)*(R5-U5)*Q5*V5/100 -> 7.3464852 | AG5: =+IF(D5="RONALD WILLIAN GARIBAY ESCUDERO",AC5+AD5+AE5+AF5+70,AC5+AD5+AE5+AF5)+70-53 -> 60.644642 | AH5: =31.1035*L5*Q5*1.1023*K5/100 -> 9.9448812 | AI5: =+((+$AI$2-R5+U5)*L5*Q5*V5)/100 -> 25.31787 | AJ5: =31.1035*1.1023*K5*P5*O5/100 -> 8.661212 | AL5: =+IF(AB5*K5>0,AB5*K5,0) -> 0 | AM5: 499
A6: IP-1076 | B6: 45677 | C6: 45671 | D6: MINERA AURIFERA 2 DE DICIEMBRE CALPA RENACE S.A. | E6: {=XLOOKUP(D6,RUC!$B$3:$B$79,RUC!$D$3:$D$79)} -> #N/A | G6: 38 | H6: MINERAL | I6: 4.05 | J6: 1.1 | K6: =+I6-(I6*(J6/100)) -> 4.00545 | L6: 1.65 | M6: 1.584 | N6: 1.634 | O6: =+ROUND((M6+N6)/2,3) -> 1.609 | P6: 90 | Q6: 89.82 | R6: 2667 | S6: 190 | U6: 90 | V6: 1.1023 | Z6: 25 | AA6: =+Y6+Z6 -> 25 | AB6: =+((O6*P6*(R6-U6)/100)-S6-AA6+T6)*V6 -> 3876.5176 | AC6: =+(S6-T6)*V6-'data 1'!$F$4 -> 129.437 | AD6: =+(Q6-P6)*(R6-U6)*L6*V6/100 -> -8.4366625 | AE6: =+(Y6*V6-70)+V6*(Z6-IF(D6="UNTUCA",IF(+((W6-3)*2.5+(X6-3)*3.1)>0,+((W6-3)*1.5+(X6-3)*3.1),0),IF(+((W6-3)*1.5+(X6-3)*3.1)>0,+((W6-3)*1.5+(X6-3)*3.1),0))) -> -42.4425 | AF6: =(L6-O6)*(R6-U6)*Q6*V6/100 -> 104.6095 | AG6: =+IF(D6="RONALD WILLIAN GARIBAY ESCUDERO",AC6+AD6+AE6+AF6+70,AC6+AD6+AE6+AF6)+70-30-5-3 -> 215.16734 | AH6: =31.1035*L6*Q6*1.1023*K6/100 -> 203.52482 | AI6: =+((+$AI$2-R6+U6)*L6*Q6*V6)/100 -> 527.66626 | AJ6: =31.1035*1.1023*K6*P6*O6/100 -> 198.86527 | AL6: =+IF(AB6*K6>0,AB6*K6,0) -> 15527.197 | AM6: =+AM4+AM5-AM3 -> 1371
A7: IP-1077 | B7: 45677 | C7: 45671 | D7: MINERA AURIFERA 2 DE DICIEMBRE CALPA RENACE S.A. | E7: {=XLOOKUP(D7,RUC!$B$3:$B$79,RUC!$D$3:$D$79)} -> #N/A | G7: 55 | H7: MINERAL | I7: 6.7 | J7: 1.2 | K7: =+I7-(I7*(J7/100)) -> 6.6196 | L7: 2.494 | M7: 2.394 | N7: 2.561 | O7: =+ROUND((M7+N7)/2,3) -> 2.478 | P7: 90 | Q7: 89.87 | R7: 2667 | S7: 190 | U7: 90 | V7: 1.1023 | Z7: 25 | AA7: =+Y7+Z7 -> 25 | AB7: =+((O7*P7*(R7-U7)/100)-S7-AA7+T7)*V7 -> 6098.1721 | AC7: =+(S7-T7)*V7-'data 1'!$F$4 -> 129.437 | AD7: =+(Q7-P7)*(R7-U7)*L7*V7/100 -> -9.2098812 | AE7: =+(Y7*V7-70)+V7*(Z7-IF(D7="UNTUCA",IF(+((W7-3)*2.5+(X7-3)*3.1)>0,+((W7-3)*1.5+(X7-3)*3.1),0),IF(+((W7-3)*1.5+(X7-3)*3.1)>0,+((W7-3)*1.5+(X7-3)*3.1),0))) -> -42.4425 | AF7: =(L7-O7)*(R7-U7)*Q7*V7/100 -> 40.845945 | AG7: =+IF(D7="RONALD WILLIAN GARIBAY ESCUDERO",AC7+AD7+AE7+AF7+70,AC7+AD7+AE7+AF7)+70-30-5-3 -> 150.63056 | AH7: =31.1035*L7*Q7*1.1023*K7/100 -> 508.6886 | AI7: =+((+$AI$2-R7+U7)*L7*Q7*V7)/100 -> 798.01953 | AJ7: =31.1035*1.1023*K7*P7*O7/100 -> 506.15628 | AL7: =+IF(AB7*K7>0,AB7*K7,0) -> 40367.46 | AM7: 600 | AN7: rec
A8: IP-1078 | B8: 45677 | C8: 45671 | D8: MINERA AURIFERA 2 DE DICIEMBRE CALPA RENACE S.A. | E8: {=XLOOKUP(D8,RUC!$B$3:$B$79,RUC!$D$3:$D$79)} -> #N/A | G8: 45 | H8: MINERAL | I8: 6.2 | J8: 1.1 | K8: =+I8-(I8*(J8/100)) -> 6.1318 | L8: 0.789 | M8: 0.757 | N8: 0.757 | O8: =+ROUND((M8+N8)/2,3) -> 0.757 | P8: 90 | Q8: 90.16 | R8: 2667 | S8: =IF((90+ROUNDDOWN(O8,1)*100)<95,95,(90+ROUNDDOWN(O8,1)*100))-5 -> 155 | U8: 90 | V8: 1.1023 | Z8: 25 | AA8: =+Y8+Z8 -> 25 | AB8: =+((O8*P8*(R8-U8)/100)-S8-AA8+T8)*V8 -> 1736.9052 | AC8: =+(S8-T8)*V8-'data 1'!$F$4 -> 90.8565 | AD8: =+(Q8-P8)*(R8-U8)*L8*V8/100 -> 3.5860077 | AE8: =+(Y8*V8-70)+V8*(Z8-IF(D8="UNTUCA",IF(+((W8-3)*2.5+(X8-3)*3.1)>0,+((W8-3)*1.5+(X8-3)*3.1),0),IF(+((W8-3)*1.5+(X8-3)*3.1)>0,+((W8-3)*1.5+(X8-3)*3.1),0))) -> -42.4425 | AF8: =(L8-O8)*(R8-U8)*Q8*V8/100 -> 81.955501 | AG8: =+IF(D8="RONALD WILLIAN GARIBAY ESCUDERO",AC8+AD8+AE8+AF8+70,AC8+AD8+AE8+AF8)+70-30-5-3 -> 165.95551 | AH8: =31.1035*L8*Q8*1.1023*K8/100 -> 149.55053 | AI8: =+((+$AI$2-R8+U8)*L8*Q8*V8)/100 -> 253.27553 | AJ8: =31.1035*1.1023*K8*P8*O8/100 -> 143.23048 | AL8: =+IF(AB8*K8>0,AB8*K8,0) -> 10650.356 | AM8: =+AM6-AM7 -> 771
A9: IP-1079 | B9: 45677 | C9: 45671 | D9: MINERA AURIFERA 2 DE DICIEMBRE CALPA RENACE S.A. | E9: {=XLOOKUP(D9,RUC!$B$3:$B$79,RUC!$D$3:$D$79)} -> #N/A | G9: 50 | H9: MINERAL | I9: 6.67 | J9: 1.2 | K9: =+I9-(I9*(J9/100)) -> 6.58996 | L9: 0.179 | M9: 0.169 | N9: 0.217 | O9: =+ROUND((M9+N9)/2,3) -> 0.193 | P9: 85 | Q9: 90.23 | R9: 2667 | S9: =IF((90+ROUNDDOWN(O9,1)*100)<95,95,(90+ROUNDDOWN(O9,1)*100))-5 -> 95 | U9: 90 | V9: 1.1023 | Z9: 25 | AA9: =+Y9+Z9 -> 25 | AB9: =+((O9*P9*(R9-U9)/100)-S9-AA9+T9)*V9 -> 333.72888 | AC9: =+(S9-T9)*V9-'data 1'!$F$4 -> 24.7185 | AD9: =+(Q9-P9)*(R9-U9)*L9*V9/100 -> 26.593099 | AE9: =+(Y9*V9-70)+V9*(Z9-IF(D9="UNTUCA",IF(+((W9-3)*2.5+(X9-3)*3.1)>0,+((W9-3)*1.5+(X9-3)*3.1),0),IF(+((W9-3)*1.5+(X9-3)*3.1)>0,+((W9-3)*1.5+(X9-3)*3.1),0))) -> -42.4425 | AF9: =(L9-O9)*(R9-U9)*Q9*V9/100 -> -35.88337 | AG9: =+IF(D9="RONALD WILLIAN GARIBAY ESCUDERO",AC9+AD9+AE9+AF9+70,AC9+AD9+AE9+AF9)+70-30-5-3 -> 4.9857291 | AH9: =31.1035*L9*Q9*1.1023*K9/100 -> 36.491846 | AI9: =+((+$AI$2-R9+U9)*L9*Q9*V9)/100 -> 57.505094 | AJ9: =31.1035*1.1023*K9*P9*O9/100 -> 37.065348 | AL9: =+IF(AB9*K9>0,AB9*K9,0) -> 2199.2599
